Workbook
Name Asset_Code: [2]Code_Dictionary!$B$12:$B$14
Name DATA1: WBS.structure!$A$2:$A$525
Name DATA10: WBS.structure!$J$2:$J$525
Name DATA11: WBS.structure!$K$2:$K$525
Name DATA12: WBS.structure!$L$2:$L$525
Name DATA13: WBS.structure!$M$2:$M$525
Name DATA14: WBS.structure!$N$2:$N$525
Name DATA15: WBS.structure!$O$2:$O$525
Name DATA16: WBS.structure!$P$2:$P$525
Name DATA17: WBS.structure!$Q$2:$Q$525
Name DATA18: WBS.structure!$R$2:$R$525
Name DATA19: WBS.structure!$S$2:$S$525
Name DATA2: WBS.structure!$B$2:$B$525
Name DATA20: WBS.structure!#REF!
Name DATA21: WBS.structure!$T$2:$T$525
Name DATA3: WBS.structure!$C$2:$C$525
Name DATA4: WBS.structure!$D$2:$D$525
Name DATA5: WBS.structure!$E$2:$E$525
Name DATA6: WBS.structure!$F$2:$F$525
Name DATA7: WBS.structure!$G$2:$G$525
Name DATA8: WBS.structure!$H$2:$H$525
Name DATA9: WBS.structure!$I$2:$I$525
Name L0_list: [2]Code_Dictionary!$C$17:$C$20
Name L1_List: [2]Code_Dictionary!$D$17:$D$20
Name L2_Code: [2]Code_Dictionary!$B$30:$B$33
Name L3_AFE_code: [2]Code_Dictionary!$F$49:$F$145
Name L3_asset_code: [2]Code_Dictionary!$E$49:$E$145
Name L3_Code: [2]Code_Dictionary!$C$49:$C$145
Name L3_Code_Desc: [2]Code_Dictionary!$H$49:$H$145
Name L3_WBS_list: [2]Code_Dictionary!$G$49:$G$145
Name Level_WBS_code: WBS.structure!$B$1:$B$2426
Name SERVICE_ITEMS: [2]Code_Dictionary!$C$1265:$C$1287
Name TEST1: WBS.structure!$A$2:$T$525
Name TESTHKEY: WBS.structure!$D$1:$T$1
Name TESTKEYS: WBS.structure!$A$2:$C$525
Name TESTVKEY: WBS.structure!$A$1:$C$1
Name WBS_ACT_USD: WBS.structure!$N$2:$N$2426
Name WBS_BUD_USD: WBS.structure!$F$2:$F$2426
Name WBS_Desc: WBS.structure!$C$2:$C$2426
Name WBS_ID: WBS.structure!$D$2:$D$2426

Sheet WBS_Dictionary
A1: # | B1: LEVEL | C1: LABEL | D1: WBS CODE | E1: LVL 1 | F1: LVL 2 | G1: LVL 3 | H1: LVL 4 | I1: LVL 5 | J1: Tag_Level_2 | K1: Tag_Level_3 | L1: Tag_Level_4 | M1: Tag_LVL5 | N1: Tag_Well_Pad | O1: Tag_Well_or_Pad | P1: Middle Number
A2: 1 | B2: 01 | C2: DRJ Drilling MUW 2023 | D2: E530-30-D235301 | E2: E530-30-D235301 | P2: =_xlfn.TEXTBEFORE(_xlfn.TEXTAFTER(Table26[[#This Row],[WBS CODE]], "-"), "-") -> 30
A3: 2 | B3: 02 | C3: Surface Facilities Cost | D3: E530-30203-D235301 | E3: E530-30-D235301 | F3: E530-30203-D235301 | J3: Surface Facilities Cost | P3: =_xlfn.TEXTBEFORE(_xlfn.TEXTAFTER(Table26[[#This Row],[WBS CODE]], "-"), "-") -> 30203
A4: 3 | B4: 03 | C4: Tie-in Pad 20 | D4: E530-3020390-D235301 | E4: E530-30-D235301 | F4: E530-30203-D235301 | G4: E530-3020390-D235301 | J4: Surface Facilities Cost | K4: Tie-in | N4: Pad 20 | O4: Pad | P4: =_xlfn.TEXTBEFORE(_xlfn.TEXTAFTER(Table26[[#This Row],[WBS CODE]], "-"), "-") -> 3020390
A5: 4 | B5: 04 | C5: Tie In - Const Pad 20 | D5: E530-302039009-D235301 | E5: E530-30-D235301 | F5: E530-30203-D235301 | G5: E530-3020390-D235301 | H5: E530-302039009-D235301 | J5: Surface Facilities Cost | K5: Tie-in | L5: Construction | N5: Pad 20 | O5: Pad | P5: =_xlfn.TEXTBEFORE(_xlfn.TEXTAFTER(Table26[[#This Row],[WBS CODE]], "-"), "-") -> 302039009
A6: 5 | B6: 05 | C6: Tie In-Inst,HookUp&Pre-Comm Pad 20 | D6: E530-30203900963-D235301 | E6: E530-30-D235301 | F6: E530-30203-D235301 | G6: E530-3020390-D235301 | H6: E530-302039009-D235301 | I6: E530-30203900963-D235301 | J6: Surface Facilities Cost | K6: Tie-in | L6: Construction | M6: Installation, Hook Up & Pre-Commisioning | N6: Pad 20 | O6: Pad | P6: =_xlfn.TEXTBEFORE(_xlfn.TEXTAFTER(Table26[[#This Row],[WBS CODE]], "-"), "-") -> 30203900963
A7: 6 | B7: 04 | C7: Tie In - Proc Pad 20 | D7: E530-302039008-D235301 | E7: E530-30-D235301 | F7: E530-30203-D235301 | G7: E530-3020390-D235301 | H7: E530-302039008-D235301 | J7: Surface Facilities Cost | K7: Tie-in | L7: Procurement | N7: Pad 20 | O7: Pad | P7: =_xlfn.TEXTBEFORE(_xlfn.TEXTAFTER(Table26[[#This Row],[WBS CODE]], "-"), "-") -> 302039008
A8: 7 | B8: 05 | C8: Tie In-Material Non LL Pad 20 | D8: E530-30203900821-D235301 | E8: E530-30-D235301 | F8: E530-30203-D235301 | G8: E530-3020390-D235301 | H8: E530-302039008-D235301 | I8: E530-30203900821-D235301 | J8: Surface Facilities Cost | K8: Tie-in | L8: Procurement | M8: Material - Non LL | N8: Pad 20 | O8: Pad | P8: =_xlfn.TEXTBEFORE(_xlfn.TEXTAFTER(Table26[[#This Row],[WBS CODE]], "-"), "-") -> 30203900821
A9: 8 | B9: 05 | C9: Tie In-Material LL Pad 20 | D9: E530-30203900860-D235301 | E9: E530-30-D235301 | F9: E530-30203-D235301 | G9: E530-3020390-D235301 | H9: E530-302039008-D235301 | I9: E530-30203900860-D235301 | J9: Surface Facilities Cost | K9: Tie-in | L9: Procurement | M9: Material - LL | N9: Pad 20 | O9: Pad | P9: =_xlfn.TEXTBEFORE(_xlfn.TEXTAFTER(Table26[[#This Row],[WBS CODE]], "-"), "-") -> 30203900860
A10: 9 | B10: 04 | C10: Tie In - Eng Pad 20 | D10: E530-302039007-D235301 | E10: E530-30-D235301 | F10: E530-30203-D235301 | G10: E530-3020390-D235301 | H10: E530-302039007-D235301 | J10: Surface Facilities Cost | K10: Tie-in | L10: Engineering | N10: Pad 20 | O10: Pad | P10: =_xlfn.TEXTBEFORE(_xlfn.TEXTAFTER(Table26[[#This Row],[WBS CODE]], "-"), "-") -> 302039007
A11: 10 | B11: 05 | C11: Tie In-Eng Pad 20 | D11: E530-30203900759-D235301 | E11: E530-30-D235301 | F11: E530-30203-D235301 | G11: E530-3020390-D235301 | H11: E530-302039007-D235301 | I11: E530-30203900759-D235301 | J11: Surface Facilities Cost | K11: Tie-in | L11: Engineering | M11: Engineering | N11: Pad 20 | O11: Pad | P11: =_xlfn.TEXTBEFORE(_xlfn.TEXTAFTER(Table26[[#This Row],[WBS CODE]], "-"), "-") -> 30203900759
A12: 11 | B12: 03 | C12: Tie-in Pad 14 | D12: E530-3020389-D235301 | E12: E530-30-D235301 | F12: E530-30203-D235301 | G12: E530-3020389-D235301 | J12: Surface Facilities Cost | K12: Tie-in | N12: Pad 14 | O12: Pad | P12: =_xlfn.TEXTBEFORE(_xlfn.TEXTAFTER(Table26[[#This Row],[WBS CODE]], "-"), "-") -> 3020389
A13: 12 | B13: 04 | C13: Tie In - Const Pad 14 | D13: E530-302038909-D235301 | E13: E530-30-D235301 | F13: E530-30203-D235301 | G13: E530-3020389-D235301 | H13: E530-302038909-D235301 | J13: Surface Facilities Cost | K13: Tie-in | L13: Construction | N13: Pad 14 | O13: Pad | P13: =_xlfn.TEXTBEFORE(_xlfn.TEXTAFTER(Table26[[#This Row],[WBS CODE]], "-"), "-") -> 302038909
A14: 13 | B14: 05 | C14: Tie In-Inst,HookUp&Pre-Comm Pad 14 | D14: E530-30203890963-D235301 | E14: E530-30-D235301 | F14: E530-30203-D235301 | G14: E530-3020389-D235301 | H14: E530-302038909-D235301 | I14: E530-30203890963-D235301 | J14: Surface Facilities Cost | K14: Tie-in | L14: Construction | M14: Installation, Hook Up & Pre-Commisioning | N14: Pad 14 | O14: Pad | P14: =_xlfn.TEXTBEFORE(_xlfn.TEXTAFTER(Table26[[#This Row],[WBS CODE]], "-"), "-") -> 30203890963
A15: 14 | B15: 04 | C15: Tie In - Proc Pad 14 | D15: E530-302038908-D235301 | E15: E530-30-D235301 | F15: E530-30203-D235301 | G15: E530-3020389-D235301 | H15: E530-302038908-D235301 | J15: Surface Facilities Cost | K15: Tie-in | L15: Procurement | N15: Pad 14 | O15: Pad | P15: =_xlfn.TEXTBEFORE(_xlfn.TEXTAFTER(Table26[[#This Row],[WBS CODE]], "-"), "-") -> 302038908
A16: 15 | B16: 05 | C16: Tie In-Material Non LL Pad 14 | D16: E530-30203890821-D235301 | E16: E530-30-D235301 | F16: E530-30203-D235301 | G16: E530-3020389-D235301 | H16: E530-302038908-D235301 | I16: E530-30203890821-D235301 | J16: Surface Facilities Cost | K16: Tie-in | L16: Procurement | M16: Material - Non LL | N16: Pad 14 | O16: Pad | P16: =_xlfn.TEXTBEFORE(_xlfn.TEXTAFTER(Table26[[#This Row],[WBS CODE]], "-"), "-") -> 30203890821
A17: 16 | B17: 05 | C17: Tie In-Material LL Pad 14 | D17: E530-30203890860-D235301 | E17: E530-30-D235301 | F17: E530-30203-D235301 | G17: E530-3020389-D235301 | H17: E530-302038908-D235301 | I17: E530-30203890860-D235301 | J17: Surface Facilities Cost | K17: Tie-in | L17: Procurement | M17: Material - LL | N17: Pad 14 | O17: Pad | P17: =_xlfn.TEXTBEFORE(_xlfn.TEXTAFTER(Table26[[#This Row],[WBS CODE]], "-"), "-") -> 30203890860
A18: 17 | B18: 04 | C18: Tie In - Eng Pad 14 | D18: E530-302038907-D235301 | E18: E530-30-D235301 | F18: E530-30203-D235301 | G18: E530-3020389-D235301 | H18: E530-302038907-D235301 | J18: Surface Facilities Cost | K18: Tie-in | L18: Engineering | N18: Pad 14 | O18: Pad | P18: =_xlfn.TEXTBEFORE(_xlfn.TEXTAFTER(Table26[[#This Row],[WBS CODE]], "-"), "-") -> 302038907
A19: 18 | B19: 05 | C19: Tie In-Eng Pad 14 | D19: E530-30203890759-D235301 | E19: E530-30-D235301 | F19: E530-30203-D235301 | G19: E530-3020389-D235301 | H19: E530-302038907-D235301 | I19: E530-30203890759-D235301 | J19: Surface Facilities Cost | K19: Tie-in | L19: Engineering | M19: Engineering | N19: Pad 14 | O19: Pad | P19: =_xlfn.TEXTBEFORE(_xlfn.TEXTAFTER(Table26[[#This Row],[WBS CODE]], "-"), "-") -> 30203890759
A20: 19 | B20: 03 | C20: Tie-in Pad 18 | D20: E530-3020388-D235301 | E20: E530-30-D235301 | F20: E530-30203-D235301 | G20: E530-3020388-D235301 | J20: Surface Facilities Cost | K20: Tie-in | N20: Pad 18 | O20: Pad | P20: =_xlfn.TEXTBEFORE(_xlfn.TEXTAFTER(Table26[[#This Row],[WBS CODE]], "-"), "-") -> 3020388
A21: 20 | B21: 04 | C21: Tie In - Const Pad 18 | D21: E530-302038809-D235301 | E21: E530-30-D235301 | F21: E530-30203-D235301 | G21: E530-3020388-D235301 | H21: E530-302038809-D235301 | J21: Surface Facilities Cost | K21: Tie-in | L21: Construction | N21: Pad 18 | O21: Pad | P21: =_xlfn.TEXTBEFORE(_xlfn.TEXTAFTER(Table26[[#This Row],[WBS CODE]], "-"), "-") -> 302038809
A22: 21 | B22: 05 | C22: Tie In-Inst,HookUp&Pre-Comm Pad 18 | D22: E530-30203880963-D235301 | E22: E530-30-D235301 | F22: E530-30203-D235301 | G22: E530-3020388-D235301 | H22: E530-302038809-D235301 | I22: E530-30203880963-D235301 | J22: Surface Facilities Cost | K22: Tie-in | L22: Construction | M22: Installation, Hook Up & Pre-Commisioning | N22: Pad 18 | O22: Pad | P22: =_xlfn.TEXTBEFORE(_xlfn.TEXTAFTER(Table26[[#This Row],[WBS CODE]], "-"), "-") -> 30203880963
A23: 22 | B23: 04 | C23: Tie In - Proc Pad 18 | D23: E530-302038808-D235301 | E23: E530-30-D235301 | F23: E530-30203-D235301 | G23: E530-3020388-D235301 | H23: E530-302038808-D235301 | J23: Surface Facilities Cost | K23: Tie-in | L23: Procurement | N23: Pad 18 | O23: Pad | P23: =_xlfn.TEXTBEFORE(_xlfn.TEXTAFTER(Table26[[#This Row],[WBS CODE]], "-"), "-") -> 302038808
A24: 23 | B24: 05 | C24: Tie In-Material Non LL Pad 18 | D24: E530-30203880821-D235301 | E24: E530-30-D235301 | F24: E530-30203-D235301 | G24: E530-3020388-D235301 | H24: E530-302038808-D235301 | I24: E530-30203880821-D235301 | J24: Surface Facilities Cost | K24: Tie-in | L24: Procurement | M24: Material - Non LL | N24: Pad 18 | O24: Pad | P24: =_xlfn.TEXTBEFORE(_xlfn.TEXTAFTER(Table26[[#This Row],[WBS CODE]], "-"), "-") -> 30203880821
A25: 24 | B25: 05 | C25: Tie In-Material LL Pad 18 | D25: E530-30203880860-D235301 | E25: E530-30-D235301 | F25: E530-30203-D235301 | G25: E530-3020388-D235301 | H25: E530-302038808-D235301 | I25: E530-30203880860-D235301 | J25: Surface Facilities Cost | K25: Tie-in | L25: Procurement | M25: Material - LL | N25: Pad 18 | O25: Pad | P25: =_xlfn.TEXTBEFORE(_xlfn.TEXTAFTER(Table26[[#This Row],[WBS CODE]], "-"), "-") -> 30203880860
A26: 25 | B26: 04 | C26: Tie In - Eng Pad 18 | D26: E530-302038807-D235301 | E26: E530-30-D235301 | F26: E530-30203-D235301 | G26: E530-3020388-D235301 | H26: E530-302038807-D235301 | J26: Surface Facilities Cost | K26: Tie-in | L26: Engineering | N26: Pad 18 | O26: Pad | P26: =_xlfn.TEXTBEFORE(_xlfn.TEXTAFTER(Table26[[#This Row],[WBS CODE]], "-"), "-") -> 302038807
A27: 26 | B27: 05 | C27: Tie In-Eng Pad 18 | D27: E530-30203880759-D235301 | E27: E530-30-D235301 | F27: E530-30203-D235301 | G27: E530-3020388-D235301 | H27: E530-302038807-D235301 | I27: E530-30203880759-D235301 | J27: Surface Facilities Cost | K27: Tie-in | L27: Engineering | M27: Engineering | N27: Pad 18 | O27: Pad | P27: =_xlfn.TEXTBEFORE(_xlfn.TEXTAFTER(Table26[[#This Row],[WBS CODE]], "-"), "-") -> 30203880759
A28: 27 | B28: 03 | C28: Tie-in Pad 15 | D28: E530-3020387-D235301 | E28: E530-30-D235301 | F28: E530-30203-D235301 | G28: E530-3020387-D235301 | J28: Surface Facilities Cost | K28: Tie-in | N28: Pad 15 | O28: Pad | P28: =_xlfn.TEXTBEFORE(_xlfn.TEXTAFTER(Table26[[#This Row],[WBS CODE]], "-"), "-") -> 3020387
A29: 28 | B29: 04 | C29: Tie In - Const Pad 15 | D29: E530-302038709-D235301 | E29: E530-30-D235301 | F29: E530-30203-D235301 | G29: E530-3020387-D235301 | H29: E530-302038709-D235301 | J29: Surface Facilities Cost | K29: Tie-in | L29: Construction | N29: Pad 15 | O29: Pad | P29: =_xlfn.TEXTBEFORE(_xlfn.TEXTAFTER(Table26[[#This Row],[WBS CODE]], "-"), "-") -> 302038709
A30: 29 | B30: 05 | C30: Tie In-Inst,HookUp&Pre-Comm Pad 15 | D30: E530-30203870963-D235301 | E30: E530-30-D235301 | F30: E530-30203-D235301 | G30: E530-3020387-D235301 | H30: E530-302038709-D235301 | I30: E530-30203870963-D235301 | J30: Surface Facilities Cost | K30: Tie-in | L30: Construction | M30: Installation, Hook Up & Pre-Commisioning | N30: Pad 15 | O30: Pad | P30: =_xlfn.TEXTBEFORE(_xlfn.TEXTAFTER(Table26[[#This Row],[WBS CODE]], "-"), "-") -> 30203870963
A31: 30 | B31: 04 | C31: Tie In - Proc Pad 15 | D31: E530-302038708-D235301 | E31: E530-30-D235301 | F31: E530-30203-D235301 | G31: E530-3020387-D235301 | H31: E530-302038708-D235301 | J31: Surface Facilities Cost | K31: Tie-in | L31: Procurement | N31: Pad 15 | O31: Pad | P31: =_xlfn.TEXTBEFORE(_xlfn.TEXTAFTER(Table26[[#This Row],[WBS CODE]], "-"), "-") -> 302038708
A32: 31 | B32: 05 | C32: Tie In-Material Non LL Pad 15 | D32: E530-30203870821-D235301 | E32: E530-30-D235301 | F32: E530-30203-D235301 | G32: E530-3020387-D235301 | H32: E530-302038708-D235301 | I32: E530-30203870821-D235301 | J32: Surface Facilities Cost | K32: Tie-in | L32: Procurement | M32: Material - Non LL | N32: Pad 15 | O32: Pad | P32: =_xlfn.TEXTBEFORE(_xlfn.TEXTAFTER(Table26[[#This Row],[WBS CODE]], "-"), "-") -> 30203870821
A33: 32 | B33: 05 | C33: Tie In-Material LL Pad 15 | D33: E530-30203870860-D235301 | E33: E530-30-D235301 | F33: E530-30203-D235301 | G33: E530-3020387-D235301 | H33: E530-302038708-D235301 | I33: E530-30203870860-D235301 | J33: Surface Facilities Cost | K33: Tie-in | L33: Procurement | M33: Material - LL | N33: Pad 15 | O33: Pad | P33: =_xlfn.TEXTBEFORE(_xlfn.TEXTAFTER(Table26[[#This Row],[WBS CODE]], "-"), "-") -> 30203870860
A34: 33 | B34: 04 | C34: Tie In - Eng Pad 15 | D34: E530-302038707-D235301 | E34: E530-30-D235301 | F34: E530-30203-D235301 | G34: E530-3020387-D235301 | H34: E530-302038707-D235301 | J34: Surface Facilities Cost | K34: Tie-in | L34: Engineering | N34: Pad 15 | O34: Pad | P34: =_xlfn.TEXTBEFORE(_xlfn.TEXTAFTER(Table26[[#This Row],[WBS CODE]], "-"), "-") -> 302038707
A35: 34 | B35: 05 | C35: Tie In-Eng Pad 15 | D35: E530-30203870759-D235301 | E35: E530-30-D235301 | F35: E530-30203-D235301 | G35: E530-3020387-D235301 | H35: E530-302038707-D235301 | I35: E530-30203870759-D235301 | J35: Surface Facilities Cost | K35: Tie-in | L35: Engineering | M35: Engineering | N35: Pad 15 | O35: Pad | P35: =_xlfn.TEXTBEFORE(_xlfn.TEXTAFTER(Table26[[#This Row],[WBS CODE]], "-"), "-") -> 30203870759
A36: 35 | B36: 03 | C36: Special Requirement Existing - Pad 20 | D36: E530-3020394-D235301 | E36: E530-30-D235301 | F36: E530-30203-D235301 | G36: E530-3020394-D235301 | J36: Surface Facilities Cost | K36: Special Requirement Existing Pad | N36: Pad 20 | O36: Pad | P36: =_xlfn.TEXTBEFORE(_xlfn.TEXTAFTER(Table26[[#This Row],[WBS CODE]], "-"), "-") -> 3020394
A37: 36 | B37: 04 | C37: Spec Req - Const Pad 20 | D37: E530-302039409-D235301 | E37: E530-30-D235301 | F37: E530-30203-D235301 | G37: E530-3020394-D235301 | H37: E530-302039409-D235301 | J37: Surface Facilities Cost | K37: Special Requirement Existing Pad | L37: Construction | N37: Pad 20 | O37: Pad | P37: =_xlfn.TEXTBEFORE(_xlfn.TEXTAFTER(Table26[[#This Row],[WBS CODE]], "-"), "-") -> 302039409
A38: 37 | B38: 05 | C38: Spec Req Const Pad 20 | D38: E530-30203940962-D235301 | E38: E530-30-D235301 | F38: E530-30203-D235301 | G38: E530-3020394-D235301 | H38: E530-302039409-D235301 | I38: E530-30203940962-D235301 | J38: Surface Facilities Cost | K38: Special Requirement Existing Pad | L38: Construction | M38: Construction | N38: Pad 20 | O38: Pad | P38: =_xlfn.TEXTBEFORE(_xlfn.TEXTAFTER(Table26[[#This Row],[WBS CODE]], "-"), "-") -> 30203940962
A39: 38 | B39: 04 | C39: Spec Req - Proc Pad 20 | D39: E530-302039408-D235301 | E39: E530-30-D235301 | F39: E530-30203-D235301 | G39: E530-3020394-D235301 | H39: E530-302039408-D235301 | J39: Surface Facilities Cost | K39: Special Requirement Existing Pad | L39: Procurement | N39: Pad 20 | O39: Pad | P39: =_xlfn.TEXTBEFORE(_xlfn.TEXTAFTER(Table26[[#This Row],[WBS CODE]], "-"), "-") -> 302039408
A40: 39 | B40: 05 | C40: Spec Req Material Non LL Pad 20 | D40: E530-30203940821-D235301 | E40: E530-30-D235301 | F40: E530-30203-D235301 | G40: E530-3020394-D235301 | H40: E530-302039408-D235301 | I40: E530-30203940821-D235301 | J40: Surface Facilities Cost | K40: Special Requirement Existing Pad | L40: Procurement | M40: Material - Non LL | N40: Pad 20 | O40: Pad | P40: =_xlfn.TEXTBEFORE(_xlfn.TEXTAFTER(Table26[[#This Row],[WBS CODE]], "-"), "-") -> 30203940821
...

Sheet WBS.structure
A1: No | B1: Level | C1: WBS_Desc | D1: WBS_ID | E1: AFE/Projec | F1: Budget | G1: Budget2 | H1: Release | I1: Release3 | J1: ProCstPlan | K1: ProCstPlan4 | L1: Tot.cst.cm | M1: Tot.cst.cm5 | N1: Act.costs | O1: Act.costs6 | P1: CAPEX | Q1: OPEX | R1: Resp.persn | S1: Life Cycle | T1: Status | U1: Code_L1 | V1: Code_L2 | W1: Code_L3 | X1: Code_L4 | Y1: LVL 5 | Z1: Tag_L2 | AA1: Tag_L3 | AB1: Tag_L4 | AC1: Tag_L5 | AD1: Tag_Well_Pad_Name | AE1: Tag_Well_or_Pad
A2: 1 | B2: 00 | C2: Salak Projects 2024 | D2: 1E54024 | F2: 76657407 | G2: USD | H2: 68353810 | I2: USD | J2: 0 | K2: USD | L2: 9271400.2 | M2: USD | N2: 38522326 | O2: USD | R2: STAR ENERGY | T2: PREL | U2: =IF(IFERROR(INDEX(WBS_Dictionary!E$2:E$1212, MATCH(Table2[[#This Row],[WBS_ID]], Table26[WBS CODE],0)), "") = "", "null", IFERROR(INDEX(WBS_Dictionary!E$2:E$1212, MATCH(Table2[[#This Row],[WBS_ID]], Table26[WBS CODE],0)), "")) -> null | V2: =IF(IFERROR(INDEX(WBS_Dictionary!F$2:F$1212, MATCH(Table2[[#This Row],[WBS_ID]], Table26[WBS CODE],0)), "") = "", "null", IFERROR(INDEX(WBS_Dictionary!F$2:F$1212, MATCH(Table2[[#This Row],[WBS_ID]], Table26[WBS CODE],0)), "")) -> null | W2: =IF(IFERROR(INDEX(WBS_Dictionary!G$2:G$1212, MATCH(Table2[[#This Row],[WBS_ID]], Table26[WBS CODE],0)), "") = "", "null", IFERROR(INDEX(WBS_Dictionary!G$2:G$1212, MATCH(Table2[[#This Row],[WBS_ID]], Table26[WBS CODE],0)), "")) -> null | X2: =IF(IFERROR(INDEX(WBS_Dictionary!H$2:H$1212, MATCH(Table2[[#This Row],[WBS_ID]], Table26[WBS CODE],0)), "") = "", "null", IFERROR(INDEX(WBS_Dictionary!H$2:H$1212, MATCH(Table2[[#This Row],[WBS_ID]], Table26[WBS CODE],0)), "")) -> null | Y2: =IF(IFERROR(INDEX(WBS_Dictionary!I$2:I$1212, MATCH(Table2[[#This Row],[WBS_ID]], Table26[WBS CODE],0)), "") = "", "null", IFERROR(INDEX(WBS_Dictionary!I$2:I$1212, MATCH(Table2[[#This Row],[WBS_ID]], Table26[WBS CODE],0)), "")) -> null | Z2: =IF(IFERROR(INDEX(WBS_Dictionary!J$2:J$1212, MATCH(Table2[[#This Row],[WBS_ID]], Table26[WBS CODE],0)), "") = "", "null", IFERROR(INDEX(WBS_Dictionary!J$2:J$1212, MATCH(Table2[[#This Row],[WBS_ID]], Table26[WBS CODE],0)), "")) -> null | AA2: =IF(IFERROR(INDEX(WBS_Dictionary!K$2:K$1212, MATCH(Table2[[#This Row],[WBS_ID]], Table26[WBS CODE],0)), "") = "", "null", IFERROR(INDEX(WBS_Dictionary!K$2:K$1212, MATCH(Table2[[#This Row],[WBS_ID]], Table26[WBS CODE],0)), "")) -> null | AB2: =IF(IFERROR(INDEX(WBS_Dictionary!L$2:L$1212, MATCH(Table2[[#This Row],[WBS_ID]], Table26[WBS CODE],0)), "") = "", "null", IFERROR(INDEX(WBS_Dictionary!L$2:L$1212, MATCH(Table2[[#This Row],[WBS_ID]], Table26[WBS CODE],0)), "")) -> null | ... AE2: =IF(IFERROR(INDEX(WBS_Dictionary!O$2:O$1212, MATCH(Table2[[#This Row],[WBS_ID]], Table26[WBS CODE],0)), "") = "", "null", IFERROR(INDEX(WBS_Dictionary!O$2:O$1212, MATCH(Table2[[#This Row],[WBS_ID]], Table26[WBS CODE],0)), "")) -> null
A3: 2 | B3: 01 | C3: SLK Drilling MUW 2025 | D3: E540-30-D245401 | E3: D245401 | F3: 76657407 | G3: USD | H3: 68353810 | I3: USD | J3: 0 | K3: USD | L3: 9271400.2 | M3: USD | N3: 38522326 | O3: USD | Q3: X | R3: STAR ENERGY | S3: Production | T3: REL BUDG AVAC // BUDG | U3: =IF(IFERROR(INDEX(WBS_Dictionary!E$2:E$1212, MATCH(Table2[[#This Row],[WBS_ID]], Table26[WBS CODE],0)), "") = "", "null", IFERROR(INDEX(WBS_Dictionary!E$2:E$1212, MATCH(Table2[[#This Row],[WBS_ID]], Table26[WBS CODE],0)), "")) -> E540-30-D245401 | V3: =IF(IFERROR(INDEX(WBS_Dictionary!F$2:F$1212, MATCH(Table2[[#This Row],[WBS_ID]], Table26[WBS CODE],0)), "") = "", "null", IFERROR(INDEX(WBS_Dictionary!F$2:F$1212, MATCH(Table2[[#This Row],[WBS_ID]], Table26[WBS CODE],0)), "")) -> null | W3: =IF(IFERROR(INDEX(WBS_Dictionary!G$2:G$1212, MATCH(Table2[[#This Row],[WBS_ID]], Table26[WBS CODE],0)), "") = "", "null", IFERROR(INDEX(WBS_Dictionary!G$2:G$1212, MATCH(Table2[[#This Row],[WBS_ID]], Table26[WBS CODE],0)), "")) -> null | X3: =IF(IFERROR(INDEX(WBS_Dictionary!H$2:H$1212, MATCH(Table2[[#This Row],[WBS_ID]], Table26[WBS CODE],0)), "") = "", "null", IFERROR(INDEX(WBS_Dictionary!H$2:H$1212, MATCH(Table2[[#This Row],[WBS_ID]], Table26[WBS CODE],0)), "")) -> null | Y3: =IF(IFERROR(INDEX(WBS_Dictionary!I$2:I$1212, MATCH(Table2[[#This Row],[WBS_ID]], Table26[WBS CODE],0)), "") = "", "null", IFERROR(INDEX(WBS_Dictionary!I$2:I$1212, MATCH(Table2[[#This Row],[WBS_ID]], Table26[WBS CODE],0)), "")) -> null | Z3: =IF(IFERROR(INDEX(WBS_Dictionary!J$2:J$1212, MATCH(Table2[[#This Row],[WBS_ID]], Table26[WBS CODE],0)), "") = "", "null", IFERROR(INDEX(WBS_Dictionary!J$2:J$1212, MATCH(Table2[[#This Row],[WBS_ID]], Table26[WBS CODE],0)), "")) -> null | AA3: =IF(IFERROR(INDEX(WBS_Dictionary!K$2:K$1212, MATCH(Table2[[#This Row],[WBS_ID]], Table26[WBS CODE],0)), "") = "", "null", IFERROR(INDEX(WBS_Dictionary!K$2:K$1212, MATCH(Table2[[#This Row],[WBS_ID]], Table26[WBS CODE],0)), "")) -> null | AB3: =IF(IFERROR(INDEX(WBS_Dictionary!L$2:L$1212, MATCH(Table2[[#This Row],[WBS_ID]], Table26[WBS CODE],0)), "") = "", "null", IFERROR(INDEX(WBS_Dictionary!L$2:L$1212, MATCH(Table2[[#This Row],[WBS_ID]], Table26[WBS CODE],0)), "")) -> null | ... AE3: =IF(IFERROR(INDEX(WBS_Dictionary!O$2:O$1212, MATCH(Table2[[#This Row],[WBS_ID]], Table26[WBS CODE],0)), "") = "", "null", IFERROR(INDEX(WBS_Dictionary!O$2:O$1212, MATCH(Table2[[#This Row],[WBS_ID]], Table26[WBS CODE],0)), "")) -> null
A4: 3 | B4: 02 | C4: Contingency | D4: E540-30299-D245401 | E4: D245401 | F4: 4950221 | G4: USD | H4: 0 | I4: USD | J4: 0 | K4: USD | L4: 0 | M4: USD | N4: 0 | O4: USD | P4: X | R4: STAR ENERGY | S4: Production | T4: REL BUDG AVAC // BUDG | U4: =IF(IFERROR(INDEX(WBS_Dictionary!E$2:E$1212, MATCH(Table2[[#This Row],[WBS_ID]], Table26[WBS CODE],0)), "") = "", "null", IFERROR(INDEX(WBS_Dictionary!E$2:E$1212, MATCH(Table2[[#This Row],[WBS_ID]], Table26[WBS CODE],0)), "")) -> E540-30-D245401 | V4: =IF(IFERROR(INDEX(WBS_Dictionary!F$2:F$1212, MATCH(Table2[[#This Row],[WBS_ID]], Table26[WBS CODE],0)), "") = "", "null", IFERROR(INDEX(WBS_Dictionary!F$2:F$1212, MATCH(Table2[[#This Row],[WBS_ID]], Table26[WBS CODE],0)), "")) -> E540-30299-D245401 | W4: =IF(IFERROR(INDEX(WBS_Dictionary!G$2:G$1212, MATCH(Table2[[#This Row],[WBS_ID]], Table26[WBS CODE],0)), "") = "", "null", IFERROR(INDEX(WBS_Dictionary!G$2:G$1212, MATCH(Table2[[#This Row],[WBS_ID]], Table26[WBS CODE],0)), "")) -> null | X4: =IF(IFERROR(INDEX(WBS_Dictionary!H$2:H$1212, MATCH(Table2[[#This Row],[WBS_ID]], Table26[WBS CODE],0)), "") = "", "null", IFERROR(INDEX(WBS_Dictionary!H$2:H$1212, MATCH(Table2[[#This Row],[WBS_ID]], Table26[WBS CODE],0)), "")) -> null | Y4: =IF(IFERROR(INDEX(WBS_Dictionary!I$2:I$1212, MATCH(Table2[[#This Row],[WBS_ID]], Table26[WBS CODE],0)), "") = "", "null", IFERROR(INDEX(WBS_Dictionary!I$2:I$1212, MATCH(Table2[[#This Row],[WBS_ID]], Table26[WBS CODE],0)), "")) -> null | Z4: =IF(IFERROR(INDEX(WBS_Dictionary!J$2:J$1212, MATCH(Table2[[#This Row],[WBS_ID]], Table26[WBS CODE],0)), "") = "", "null", IFERROR(INDEX(WBS_Dictionary!J$2:J$1212, MATCH(Table2[[#This Row],[WBS_ID]], Table26[WBS CODE],0)), "")) -> Contingency | AA4: =IF(IFERROR(INDEX(WBS_Dictionary!K$2:K$1212, MATCH(Table2[[#This Row],[WBS_ID]], Table26[WBS CODE],0)), "") = "", "null", IFERROR(INDEX(WBS_Dictionary!K$2:K$1212, MATCH(Table2[[#This Row],[WBS_ID]], Table26[WBS CODE],0)), "")) -> null | AB4: =IF(IFERROR(INDEX(WBS_Dictionary!L$2:L$1212, MATCH(Table2[[#This Row],[WBS_ID]], Table26[WBS CODE],0)), "") = "", "null", IFERROR(INDEX(WBS_Dictionary!L$2:L$1212, MATCH(Table2[[#This Row],[WBS_ID]], Table26[WBS CODE],0)), "")) -> null | ... AE4: =IF(IFERROR(INDEX(WBS_Dictionary!O$2:O$1212, MATCH(Table2[[#This Row],[WBS_ID]], Table26[WBS CODE],0)), "") = "", "null", IFERROR(INDEX(WBS_Dictionary!O$2:O$1212, MATCH(Table2[[#This Row],[WBS_ID]], Table26[WBS CODE],0)), "")) -> null
A5: 4 | B5: 03 | C5: Contingency | D5: E540-3029901-D245401 | E5: D245401 | F5: 4950221 | G5: USD | H5: 0 | I5: USD | J5: 0 | K5: USD | L5: 0 | M5: USD | N5: 0 | O5: USD | P5: X | R5: STAR ENERGY | S5: Production | T5: REL BUDG AVAC // BUDG | U5: =IF(IFERROR(INDEX(WBS_Dictionary!E$2:E$1212, MATCH(Table2[[#This Row],[WBS_ID]], Table26[WBS CODE],0)), "") = "", "null", IFERROR(INDEX(WBS_Dictionary!E$2:E$1212, MATCH(Table2[[#This Row],[WBS_ID]], Table26[WBS CODE],0)), "")) -> E540-30-D245401 | V5: =IF(IFERROR(INDEX(WBS_Dictionary!F$2:F$1212, MATCH(Table2[[#This Row],[WBS_ID]], Table26[WBS CODE],0)), "") = "", "null", IFERROR(INDEX(WBS_Dictionary!F$2:F$1212, MATCH(Table2[[#This Row],[WBS_ID]], Table26[WBS CODE],0)), "")) -> E540-30299-D245401 | W5: =IF(IFERROR(INDEX(WBS_Dictionary!G$2:G$1212, MATCH(Table2[[#This Row],[WBS_ID]], Table26[WBS CODE],0)), "") = "", "null", IFERROR(INDEX(WBS_Dictionary!G$2:G$1212, MATCH(Table2[[#This Row],[WBS_ID]], Table26[WBS CODE],0)), "")) -> E540-3029901-D245401 | X5: =IF(IFERROR(INDEX(WBS_Dictionary!H$2:H$1212, MATCH(Table2[[#This Row],[WBS_ID]], Table26[WBS CODE],0)), "") = "", "null", IFERROR(INDEX(WBS_Dictionary!H$2:H$1212, MATCH(Table2[[#This Row],[WBS_ID]], Table26[WBS CODE],0)), "")) -> null | Y5: =IF(IFERROR(INDEX(WBS_Dictionary!I$2:I$1212, MATCH(Table2[[#This Row],[WBS_ID]], Table26[WBS CODE],0)), "") = "", "null", IFERROR(INDEX(WBS_Dictionary!I$2:I$1212, MATCH(Table2[[#This Row],[WBS_ID]], Table26[WBS CODE],0)), "")) -> null | Z5: =IF(IFERROR(INDEX(WBS_Dictionary!J$2:J$1212, MATCH(Table2[[#This Row],[WBS_ID]], Table26[WBS CODE],0)), "") = "", "null", IFERROR(INDEX(WBS_Dictionary!J$2:J$1212, MATCH(Table2[[#This Row],[WBS_ID]], Table26[WBS CODE],0)), "")) -> Contingency | AA5: =IF(IFERROR(INDEX(WBS_Dictionary!K$2:K$1212, MATCH(Table2[[#This Row],[WBS_ID]], Table26[WBS CODE],0)), "") = "", "null", IFERROR(INDEX(WBS_Dictionary!K$2:K$1212, MATCH(Table2[[#This Row],[WBS_ID]], Table26[WBS CODE],0)), "")) -> Contingency | AB5: =IF(IFERROR(INDEX(WBS_Dictionary!L$2:L$1212, MATCH(Table2[[#This Row],[WBS_ID]], Table26[WBS CODE],0)), "") = "", "null", IFERROR(INDEX(WBS_Dictionary!L$2:L$1212, MATCH(Table2[[#This Row],[WBS_ID]], Table26[WBS CODE],0)), "")) -> null | ... AE5: =IF(IFERROR(INDEX(WBS_Dictionary!O$2:O$1212, MATCH(Table2[[#This Row],[WBS_ID]], Table26[WBS CODE],0)), "") = "", "null", IFERROR(INDEX(WBS_Dictionary!O$2:O$1212, MATCH(Table2[[#This Row],[WBS_ID]], Table26[WBS CODE],0)), "")) -> null
A6: 5 | B6: 04 | C6: Contingency | D6: E540-302990115-D245401 | E6: D245401 | F6: 4950221 | G6: USD | H6: 0 | I6: USD | J6: 0 | K6: USD | L6: 0 | M6: USD | N6: 0 | O6: USD | P6: X | R6: STAR ENERGY | S6: Production | T6: REL BUDG AVAC // BUDG | U6: =IF(IFERROR(INDEX(WBS_Dictionary!E$2:E$1212, MATCH(Table2[[#This Row],[WBS_ID]], Table26[WBS CODE],0)), "") = "", "null", IFERROR(INDEX(WBS_Dictionary!E$2:E$1212, MATCH(Table2[[#This Row],[WBS_ID]], Table26[WBS CODE],0)), "")) -> E540-30-D245401 | V6: =IF(IFERROR(INDEX(WBS_Dictionary!F$2:F$1212, MATCH(Table2[[#This Row],[WBS_ID]], Table26[WBS CODE],0)), "") = "", "null", IFERROR(INDEX(WBS_Dictionary!F$2:F$1212, MATCH(Table2[[#This Row],[WBS_ID]], Table26[WBS CODE],0)), "")) -> E540-30299-D245401 | W6: =IF(IFERROR(INDEX(WBS_Dictionary!G$2:G$1212, MATCH(Table2[[#This Row],[WBS_ID]], Table26[WBS CODE],0)), "") = "", "null", IFERROR(INDEX(WBS_Dictionary!G$2:G$1212, MATCH(Table2[[#This Row],[WBS_ID]], Table26[WBS CODE],0)), "")) -> E540-3029901-D245401 | X6: =IF(IFERROR(INDEX(WBS_Dictionary!H$2:H$1212, MATCH(Table2[[#This Row],[WBS_ID]], Table26[WBS CODE],0)), "") = "", "null", IFERROR(INDEX(WBS_Dictionary!H$2:H$1212, MATCH(Table2[[#This Row],[WBS_ID]], Table26[WBS CODE],0)), "")) -> E540-302990115-D245401 | Y6: =IF(IFERROR(INDEX(WBS_Dictionary!I$2:I$1212, MATCH(Table2[[#This Row],[WBS_ID]], Table26[WBS CODE],0)), "") = "", "null", IFERROR(INDEX(WBS_Dictionary!I$2:I$1212, MATCH(Table2[[#This Row],[WBS_ID]], Table26[WBS CODE],0)), "")) -> null | Z6: =IF(IFERROR(INDEX(WBS_Dictionary!J$2:J$1212, MATCH(Table2[[#This Row],[WBS_ID]], Table26[WBS CODE],0)), "") = "", "null", IFERROR(INDEX(WBS_Dictionary!J$2:J$1212, MATCH(Table2[[#This Row],[WBS_ID]], Table26[WBS CODE],0)), "")) -> Contingency | AA6: =IF(IFERROR(INDEX(WBS_Dictionary!K$2:K$1212, MATCH(Table2[[#This Row],[WBS_ID]], Table26[WBS CODE],0)), "") = "", "null", IFERROR(INDEX(WBS_Dictionary!K$2:K$1212, MATCH(Table2[[#This Row],[WBS_ID]], Table26[WBS CODE],0)), "")) -> Contingency | AB6: =IF(IFERROR(INDEX(WBS_Dictionary!L$2:L$1212, MATCH(Table2[[#This Row],[WBS_ID]], Table26[WBS CODE],0)), "") = "", "null", IFERROR(INDEX(WBS_Dictionary!L$2:L$1212, MATCH(Table2[[#This Row],[WBS_ID]], Table26[WBS CODE],0)), "")) -> Contingency | ... AE6: =IF(IFERROR(INDEX(WBS_Dictionary!O$2:O$1212, MATCH(Table2[[#This Row],[WBS_ID]], Table26[WBS CODE],0)), "") = "", "null", IFERROR(INDEX(WBS_Dictionary!O$2:O$1212, MATCH(Table2[[#This Row],[WBS_ID]], Table26[WBS CODE],0)), "")) -> null
A7: 6 | B7: 05 | C7: Contingency | D7: E540-30299011521-D245401 | E7: D245401 | F7: 0 | G7: USD | H7: 0 | I7: USD | J7: 0 | K7: USD | L7: 0 | M7: USD | N7: 0 | O7: USD | P7: X | R7: STAR ENERGY | S7: Production | T7: REL AVAC // BUDG | U7: =IF(IFERROR(INDEX(WBS_Dictionary!E$2:E$1212, MATCH(Table2[[#This Row],[WBS_ID]], Table26[WBS CODE],0)), "") = "", "null", IFERROR(INDEX(WBS_Dictionary!E$2:E$1212, MATCH(Table2[[#This Row],[WBS_ID]], Table26[WBS CODE],0)), "")) -> E540-30-D245401 | V7: =IF(IFERROR(INDEX(WBS_Dictionary!F$2:F$1212, MATCH(Table2[[#This Row],[WBS_ID]], Table26[WBS CODE],0)), "") = "", "null", IFERROR(INDEX(WBS_Dictionary!F$2:F$1212, MATCH(Table2[[#This Row],[WBS_ID]], Table26[WBS CODE],0)), "")) -> E540-30299-D245401 | W7: =IF(IFERROR(INDEX(WBS_Dictionary!G$2:G$1212, MATCH(Table2[[#This Row],[WBS_ID]], Table26[WBS CODE],0)), "") = "", "null", IFERROR(INDEX(WBS_Dictionary!G$2:G$1212, MATCH(Table2[[#This Row],[WBS_ID]], Table26[WBS CODE],0)), "")) -> E540-3029901-D245401 | X7: =IF(IFERROR(INDEX(WBS_Dictionary!H$2:H$1212, MATCH(Table2[[#This Row],[WBS_ID]], Table26[WBS CODE],0)), "") = "", "null", IFERROR(INDEX(WBS_Dictionary!H$2:H$1212, MATCH(Table2[[#This Row],[WBS_ID]], Table26[WBS CODE],0)), "")) -> E540-302990115-D245401 | Y7: =IF(IFERROR(INDEX(WBS_Dictionary!I$2:I$1212, MATCH(Table2[[#This Row],[WBS_ID]], Table26[WBS CODE],0)), "") = "", "null", IFERROR(INDEX(WBS_Dictionary!I$2:I$1212, MATCH(Table2[[#This Row],[WBS_ID]], Table26[WBS CODE],0)), "")) -> E540-30299011521-D245401 | Z7: =IF(IFERROR(INDEX(WBS_Dictionary!J$2:J$1212, MATCH(Table2[[#This Row],[WBS_ID]], Table26[WBS CODE],0)), "") = "", "null", IFERROR(INDEX(WBS_Dictionary!J$2:J$1212, MATCH(Table2[[#This Row],[WBS_ID]], Table26[WBS CODE],0)), "")) -> Contingency | AA7: =IF(IFERROR(INDEX(WBS_Dictionary!K$2:K$1212, MATCH(Table2[[#This Row],[WBS_ID]], Table26[WBS CODE],0)), "") = "", "null", IFERROR(INDEX(WBS_Dictionary!K$2:K$1212, MATCH(Table2[[#This Row],[WBS_ID]], Table26[WBS CODE],0)), "")) -> Contingency | AB7: =IF(IFERROR(INDEX(WBS_Dictionary!L$2:L$1212, MATCH(Table2[[#This Row],[WBS_ID]], Table26[WBS CODE],0)), "") = "", "null", IFERROR(INDEX(WBS_Dictionary!L$2:L$1212, MATCH(Table2[[#This Row],[WBS_ID]], Table26[WBS CODE],0)), "")) -> Contingency | ... AE7: =IF(IFERROR(INDEX(WBS_Dictionary!O$2:O$1212, MATCH(Table2[[#This Row],[WBS_ID]], Table26[WBS CODE],0)), "") = "", "null", IFERROR(INDEX(WBS_Dictionary!O$2:O$1212, MATCH(Table2[[#This Row],[WBS_ID]], Table26[WBS CODE],0)), "")) -> null
A8: 7 | B8: 02 | C8: Surface Facilities Cost | D8: E540-30203-D245401 | E8: D245401 | F8: 12318779 | G8: USD | H8: 11266879 | I8: USD | J8: 0 | K8: USD | L8: 1677993.4 | M8: USD | N8: 4621324.5 | O8: USD | P8: X | R8: STAR ENERGY | S8: Production | T8: REL BUDG AVAC // BUDG | U8: =IF(IFERROR(INDEX(WBS_Dictionary!E$2:E$1212, MATCH(Table2[[#This Row],[WBS_ID]], Table26[WBS CODE],0)), "") = "", "null", IFERROR(INDEX(WBS_Dictionary!E$2:E$1212, MATCH(Table2[[#This Row],[WBS_ID]], Table26[WBS CODE],0)), "")) -> E540-30-D245401 | V8: =IF(IFERROR(INDEX(WBS_Dictionary!F$2:F$1212, MATCH(Table2[[#This Row],[WBS_ID]], Table26[WBS CODE],0)), "") = "", "null", IFERROR(INDEX(WBS_Dictionary!F$2:F$1212, MATCH(Table2[[#This Row],[WBS_ID]], Table26[WBS CODE],0)), "")) -> E540-30203-D245401 | W8: =IF(IFERROR(INDEX(WBS_Dictionary!G$2:G$1212, MATCH(Table2[[#This Row],[WBS_ID]], Table26[WBS CODE],0)), "") = "", "null", IFERROR(INDEX(WBS_Dictionary!G$2:G$1212, MATCH(Table2[[#This Row],[WBS_ID]], Table26[WBS CODE],0)), "")) -> null | X8: =IF(IFERROR(INDEX(WBS_Dictionary!H$2:H$1212, MATCH(Table2[[#This Row],[WBS_ID]], Table26[WBS CODE],0)), "") = "", "null", IFERROR(INDEX(WBS_Dictionary!H$2:H$1212, MATCH(Table2[[#This Row],[WBS_ID]], Table26[WBS CODE],0)), "")) -> null | Y8: =IF(IFERROR(INDEX(WBS_Dictionary!I$2:I$1212, MATCH(Table2[[#This Row],[WBS_ID]], Table26[WBS CODE],0)), "") = "", "null", IFERROR(INDEX(WBS_Dictionary!I$2:I$1212, MATCH(Table2[[#This Row],[WBS_ID]], Table26[WBS CODE],0)), "")) -> null | Z8: =IF(IFERROR(INDEX(WBS_Dictionary!J$2:J$1212, MATCH(Table2[[#This Row],[WBS_ID]], Table26[WBS CODE],0)), "") = "", "null", IFERROR(INDEX(WBS_Dictionary!J$2:J$1212, MATCH(Table2[[#This Row],[WBS_ID]], Table26[WBS CODE],0)), "")) -> Surface Facilities Cost | AA8: =IF(IFERROR(INDEX(WBS_Dictionary!K$2:K$1212, MATCH(Table2[[#This Row],[WBS_ID]], Table26[WBS CODE],0)), "") = "", "null", IFERROR(INDEX(WBS_Dictionary!K$2:K$1212, MATCH(Table2[[#This Row],[WBS_ID]], Table26[WBS CODE],0)), "")) -> null | AB8: =IF(IFERROR(INDEX(WBS_Dictionary!L$2:L$1212, MATCH(Table2[[#This Row],[WBS_ID]], Table26[WBS CODE],0)), "") = "", "null", IFERROR(INDEX(WBS_Dictionary!L$2:L$1212, MATCH(Table2[[#This Row],[WBS_ID]], Table26[WBS CODE],0)), "")) -> null | ... AE8: =IF(IFERROR(INDEX(WBS_Dictionary!O$2:O$1212, MATCH(Table2[[#This Row],[WBS_ID]], Table26[WBS CODE],0)), "") = "", "null", IFERROR(INDEX(WBS_Dictionary!O$2:O$1212, MATCH(Table2[[#This Row],[WBS_ID]], Table26[WBS CODE],0)), "")) -> null
A9: 8 | B9: 03 | C9: New Rig Pavement | D9: E540-3020393-D245401 | E9: D245401 | F9: 1051900 | G9: USD | H9: 0 | I9: USD | J9: 0 | K9: USD | L9: 0 | M9: USD | N9: 0 | O9: USD | P9: X | R9: STAR ENERGY | S9: Production | T9: REL BUDG AVAC // BUDG | U9: =IF(IFERROR(INDEX(WBS_Dictionary!E$2:E$1212, MATCH(Table2[[#This Row],[WBS_ID]], Table26[WBS CODE],0)), "") = "", "null", IFERROR(INDEX(WBS_Dictionary!E$2:E$1212, MATCH(Table2[[#This Row],[WBS_ID]], Table26[WBS CODE],0)), "")) -> E540-30-D245401 | V9: =IF(IFERROR(INDEX(WBS_Dictionary!F$2:F$1212, MATCH(Table2[[#This Row],[WBS_ID]], Table26[WBS CODE],0)), "") = "", "null", IFERROR(INDEX(WBS_Dictionary!F$2:F$1212, MATCH(Table2[[#This Row],[WBS_ID]], Table26[WBS CODE],0)), "")) -> E540-30203-D245401 | W9: =IF(IFERROR(INDEX(WBS_Dictionary!G$2:G$1212, MATCH(Table2[[#This Row],[WBS_ID]], Table26[WBS CODE],0)), "") = "", "null", IFERROR(INDEX(WBS_Dictionary!G$2:G$1212, MATCH(Table2[[#This Row],[WBS_ID]], Table26[WBS CODE],0)), "")) -> E540-3020393-D245401 | X9: =IF(IFERROR(INDEX(WBS_Dictionary!H$2:H$1212, MATCH(Table2[[#This Row],[WBS_ID]], Table26[WBS CODE],0)), "") = "", "null", IFERROR(INDEX(WBS_Dictionary!H$2:H$1212, MATCH(Table2[[#This Row],[WBS_ID]], Table26[WBS CODE],0)), "")) -> null | Y9: =IF(IFERROR(INDEX(WBS_Dictionary!I$2:I$1212, MATCH(Table2[[#This Row],[WBS_ID]], Table26[WBS CODE],0)), "") = "", "null", IFERROR(INDEX(WBS_Dictionary!I$2:I$1212, MATCH(Table2[[#This Row],[WBS_ID]], Table26[WBS CODE],0)), "")) -> null | Z9: =IF(IFERROR(INDEX(WBS_Dictionary!J$2:J$1212, MATCH(Table2[[#This Row],[WBS_ID]], Table26[WBS CODE],0)), "") = "", "null", IFERROR(INDEX(WBS_Dictionary!J$2:J$1212, MATCH(Table2[[#This Row],[WBS_ID]], Table26[WBS CODE],0)), "")) -> Surface Facilities Cost | AA9: =IF(IFERROR(INDEX(WBS_Dictionary!K$2:K$1212, MATCH(Table2[[#This Row],[WBS_ID]], Table26[WBS CODE],0)), "") = "", "null", IFERROR(INDEX(WBS_Dictionary!K$2:K$1212, MATCH(Table2[[#This Row],[WBS_ID]], Table26[WBS CODE],0)), "")) -> New Rig Pavement | AB9: =IF(IFERROR(INDEX(WBS_Dictionary!L$2:L$1212, MATCH(Table2[[#This Row],[WBS_ID]], Table26[WBS CODE],0)), "") = "", "null", IFERROR(INDEX(WBS_Dictionary!L$2:L$1212, MATCH(Table2[[#This Row],[WBS_ID]], Table26[WBS CODE],0)), "")) -> null | ... AE9: =IF(IFERROR(INDEX(WBS_Dictionary!O$2:O$1212, MATCH(Table2[[#This Row],[WBS_ID]], Table26[WBS CODE],0)), "") = "", "null", IFERROR(INDEX(WBS_Dictionary!O$2:O$1212, MATCH(Table2[[#This Row],[WBS_ID]], Table26[WBS CODE],0)), "")) -> null
A10: 9 | B10: 04 | C10: New Rig Pavement | D10: E540-302039309-D245401 | E10: D245401 | F10: 0 | G10: USD | H10: 0 | I10: USD | J10: 0 | K10: USD | L10: 0 | M10: USD | N10: 0 | O10: USD | P10: X | R10: STAR ENERGY | S10: Production | T10: REL AVAC // BUDG | U10: =IF(IFERROR(INDEX(WBS_Dictionary!E$2:E$1212, MATCH(Table2[[#This Row],[WBS_ID]], Table26[WBS CODE],0)), "") = "", "null", IFERROR(INDEX(WBS_Dictionary!E$2:E$1212, MATCH(Table2[[#This Row],[WBS_ID]], Table26[WBS CODE],0)), "")) -> E540-30-D245401 | V10: =IF(IFERROR(INDEX(WBS_Dictionary!F$2:F$1212, MATCH(Table2[[#This Row],[WBS_ID]], Table26[WBS CODE],0)), "") = "", "null", IFERROR(INDEX(WBS_Dictionary!F$2:F$1212, MATCH(Table2[[#This Row],[WBS_ID]], Table26[WBS CODE],0)), "")) -> E540-30203-D245401 | W10: =IF(IFERROR(INDEX(WBS_Dictionary!G$2:G$1212, MATCH(Table2[[#This Row],[WBS_ID]], Table26[WBS CODE],0)), "") = "", "null", IFERROR(INDEX(WBS_Dictionary!G$2:G$1212, MATCH(Table2[[#This Row],[WBS_ID]], Table26[WBS CODE],0)), "")) -> E540-3020393-D245401 | X10: =IF(IFERROR(INDEX(WBS_Dictionary!H$2:H$1212, MATCH(Table2[[#This Row],[WBS_ID]], Table26[WBS CODE],0)), "") = "", "null", IFERROR(INDEX(WBS_Dictionary!H$2:H$1212, MATCH(Table2[[#This Row],[WBS_ID]], Table26[WBS CODE],0)), "")) -> E540-302039309-D245401 | Y10: =IF(IFERROR(INDEX(WBS_Dictionary!I$2:I$1212, MATCH(Table2[[#This Row],[WBS_ID]], Table26[WBS CODE],0)), "") = "", "null", IFERROR(INDEX(WBS_Dictionary!I$2:I$1212, MATCH(Table2[[#This Row],[WBS_ID]], Table26[WBS CODE],0)), "")) -> null | Z10: =IF(IFERROR(INDEX(WBS_Dictionary!J$2:J$1212, MATCH(Table2[[#This Row],[WBS_ID]], Table26[WBS CODE],0)), "") = "", "null", IFERROR(INDEX(WBS_Dictionary!J$2:J$1212, MATCH(Table2[[#This Row],[WBS_ID]], Table26[WBS CODE],0)), "")) -> Surface Facilities Cost | AA10: =IF(IFERROR(INDEX(WBS_Dictionary!K$2:K$1212, MATCH(Table2[[#This Row],[WBS_ID]], Table26[WBS CODE],0)), "") = "", "null", IFERROR(INDEX(WBS_Dictionary!K$2:K$1212, MATCH(Table2[[#This Row],[WBS_ID]], Table26[WBS CODE],0)), "")) -> New Rig Pavement | AB10: =IF(IFERROR(INDEX(WBS_Dictionary!L$2:L$1212, MATCH(Table2[[#This Row],[WBS_ID]], Table26[WBS CODE],0)), "") = "", "null", IFERROR(INDEX(WBS_Dictionary!L$2:L$1212, MATCH(Table2[[#This Row],[WBS_ID]], Table26[WBS CODE],0)), "")) -> Construction | ... AE10: =IF(IFERROR(INDEX(WBS_Dictionary!O$2:O$1212, MATCH(Table2[[#This Row],[WBS_ID]], Table26[WBS CODE],0)), "") = "", "null", IFERROR(INDEX(WBS_Dictionary!O$2:O$1212, MATCH(Table2[[#This Row],[WBS_ID]], Table26[WBS CODE],0)), "")) -> null
A11: 10 | B11: 05 | C11: New Rig Pavement | D11: E540-30203930961-D245401 | E11: D245401 | F11: 0 | G11: USD | H11: 0 | I11: USD | J11: 0 | K11: USD | L11: 0 | M11: USD | N11: 0 | O11: USD | P11: X | R11: STAR ENERGY | S11: Production | T11: REL AVAC // BUDG | U11: =IF(IFERROR(INDEX(WBS_Dictionary!E$2:E$1212, MATCH(Table2[[#This Row],[WBS_ID]], Table26[WBS CODE],0)), "") = "", "null", IFERROR(INDEX(WBS_Dictionary!E$2:E$1212, MATCH(Table2[[#This Row],[WBS_ID]], Table26[WBS CODE],0)), "")) -> E540-30-D245401 | V11: =IF(IFERROR(INDEX(WBS_Dictionary!F$2:F$1212, MATCH(Table2[[#This Row],[WBS_ID]], Table26[WBS CODE],0)), "") = "", "null", IFERROR(INDEX(WBS_Dictionary!F$2:F$1212, MATCH(Table2[[#This Row],[WBS_ID]], Table26[WBS CODE],0)), "")) -> E540-30203-D245401 | W11: =IF(IFERROR(INDEX(WBS_Dictionary!G$2:G$1212, MATCH(Table2[[#This Row],[WBS_ID]], Table26[WBS CODE],0)), "") = "", "null", IFERROR(INDEX(WBS_Dictionary!G$2:G$1212, MATCH(Table2[[#This Row],[WBS_ID]], Table26[WBS CODE],0)), "")) -> E540-3020393-D245401 | X11: =IF(IFERROR(INDEX(WBS_Dictionary!H$2:H$1212, MATCH(Table2[[#This Row],[WBS_ID]], Table26[WBS CODE],0)), "") = "", "null", IFERROR(INDEX(WBS_Dictionary!H$2:H$1212, MATCH(Table2[[#This Row],[WBS_ID]], Table26[WBS CODE],0)), "")) -> E540-302039309-D245401 | Y11: =IF(IFERROR(INDEX(WBS_Dictionary!I$2:I$1212, MATCH(Table2[[#This Row],[WBS_ID]], Table26[WBS CODE],0)), "") = "", "null", IFERROR(INDEX(WBS_Dictionary!I$2:I$1212, MATCH(Table2[[#This Row],[WBS_ID]], Table26[WBS CODE],0)), "")) -> E540-30203930961-D245401 | Z11: =IF(IFERROR(INDEX(WBS_Dictionary!J$2:J$1212, MATCH(Table2[[#This Row],[WBS_ID]], Table26[WBS CODE],0)), "") = "", "null", IFERROR(INDEX(WBS_Dictionary!J$2:J$1212, MATCH(Table2[[#This Row],[WBS_ID]], Table26[WBS CODE],0)), "")) -> Surface Facilities Cost | AA11: =IF(IFERROR(INDEX(WBS_Dictionary!K$2:K$1212, MATCH(Table2[[#This Row],[WBS_ID]], Table26[WBS CODE],0)), "") = "", "null", IFERROR(INDEX(WBS_Dictionary!K$2:K$1212, MATCH(Table2[[#This Row],[WBS_ID]], Table26[WBS CODE],0)), "")) -> New Rig Pavement | AB11: =IF(IFERROR(INDEX(WBS_Dictionary!L$2:L$1212, MATCH(Table2[[#This Row],[WBS_ID]], Table26[WBS CODE],0)), "") = "", "null", IFERROR(INDEX(WBS_Dictionary!L$2:L$1212, MATCH(Table2[[#This Row],[WBS_ID]], Table26[WBS CODE],0)), "")) -> Construction | ... AE11: =IF(IFERROR(INDEX(WBS_Dictionary!O$2:O$1212, MATCH(Table2[[#This Row],[WBS_ID]], Table26[WBS CODE],0)), "") = "", "null", IFERROR(INDEX(WBS_Dictionary!O$2:O$1212, MATCH(Table2[[#This Row],[WBS_ID]], Table26[WBS CODE],0)), "")) -> null
A12: 11 | B12: 03 | C12: Tie-in AWI3 | D12: E540-3020394-D245401 | E12: D245401 | F12: 442618.13 | G12: USD | H12: 442618.13 | I12: USD | J12: 0 | K12: USD | L12: 18695.05 | M12: USD | N12: 336073.61 | O12: USD | P12: X | R12: STAR ENERGY | S12: Production | T12: REL BUDG AVAC // BUDG | U12: =IF(IFERROR(INDEX(WBS_Dictionary!E$2:E$1212, MATCH(Table2[[#This Row],[WBS_ID]], Table26[WBS CODE],0)), "") = "", "null", IFERROR(INDEX(WBS_Dictionary!E$2:E$1212, MATCH(Table2[[#This Row],[WBS_ID]], Table26[WBS CODE],0)), "")) -> E540-30-D245401 | V12: =IF(IFERROR(INDEX(WBS_Dictionary!F$2:F$1212, MATCH(Table2[[#This Row],[WBS_ID]], Table26[WBS CODE],0)), "") = "", "null", IFERROR(INDEX(WBS_Dictionary!F$2:F$1212, MATCH(Table2[[#This Row],[WBS_ID]], Table26[WBS CODE],0)), "")) -> E540-30203-D245401 | W12: =IF(IFERROR(INDEX(WBS_Dictionary!G$2:G$1212, MATCH(Table2[[#This Row],[WBS_ID]], Table26[WBS CODE],0)), "") = "", "null", IFERROR(INDEX(WBS_Dictionary!G$2:G$1212, MATCH(Table2[[#This Row],[WBS_ID]], Table26[WBS CODE],0)), "")) -> E540-3020394-D245401 | X12: =IF(IFERROR(INDEX(WBS_Dictionary!H$2:H$1212, MATCH(Table2[[#This Row],[WBS_ID]], Table26[WBS CODE],0)), "") = "", "null", IFERROR(INDEX(WBS_Dictionary!H$2:H$1212, MATCH(Table2[[#This Row],[WBS_ID]], Table26[WBS CODE],0)), "")) -> null | Y12: =IF(IFERROR(INDEX(WBS_Dictionary!I$2:I$1212, MATCH(Table2[[#This Row],[WBS_ID]], Table26[WBS CODE],0)), "") = "", "null", IFERROR(INDEX(WBS_Dictionary!I$2:I$1212, MATCH(Table2[[#This Row],[WBS_ID]], Table26[WBS CODE],0)), "")) -> null | Z12: =IF(IFERROR(INDEX(WBS_Dictionary!J$2:J$1212, MATCH(Table2[[#This Row],[WBS_ID]], Table26[WBS CODE],0)), "") = "", "null", IFERROR(INDEX(WBS_Dictionary!J$2:J$1212, MATCH(Table2[[#This Row],[WBS_ID]], Table26[WBS CODE],0)), "")) -> Surface Facilities Cost | AA12: =IF(IFERROR(INDEX(WBS_Dictionary!K$2:K$1212, MATCH(Table2[[#This Row],[WBS_ID]], Table26[WBS CODE],0)), "") = "", "null", IFERROR(INDEX(WBS_Dictionary!K$2:K$1212, MATCH(Table2[[#This Row],[WBS_ID]], Table26[WBS CODE],0)), "")) -> Tie-in | AB12: =IF(IFERROR(INDEX(WBS_Dictionary!L$2:L$1212, MATCH(Table2[[#This Row],[WBS_ID]], Table26[WBS CODE],0)), "") = "", "null", IFERROR(INDEX(WBS_Dictionary!L$2:L$1212, MATCH(Table2[[#This Row],[WBS_ID]], Table26[WBS CODE],0)), "")) -> null | ... AE12: =IF(IFERROR(INDEX(WBS_Dictionary!O$2:O$1212, MATCH(Table2[[#This Row],[WBS_ID]], Table26[WBS CODE],0)), "") = "", "null", IFERROR(INDEX(WBS_Dictionary!O$2:O$1212, MATCH(Table2[[#This Row],[WBS_ID]], Table26[WBS CODE],0)), "")) -> Pad
A13: 12 | B13: 04 | C13: Tie In - Const Pad AWI3 | D13: E540-302039409-D245401 | E13: D245401 | F13: 186765.16 | G13: USD | H13: 186765.16 | I13: USD | J13: 0 | K13: USD | L13: 11341.6 | M13: USD | N13: 143570.32 | O13: USD | P13: X | R13: STAR ENERGY | S13: Production | T13: REL BUDG ISBD AVAC // BUDG | U13: =IF(IFERROR(INDEX(WBS_Dictionary!E$2:E$1212, MATCH(Table2[[#This Row],[WBS_ID]], Table26[WBS CODE],0)), "") = "", "null", IFERROR(INDEX(WBS_Dictionary!E$2:E$1212, MATCH(Table2[[#This Row],[WBS_ID]], Table26[WBS CODE],0)), "")) -> E540-30-D245401 | V13: =IF(IFERROR(INDEX(WBS_Dictionary!F$2:F$1212, MATCH(Table2[[#This Row],[WBS_ID]], Table26[WBS CODE],0)), "") = "", "null", IFERROR(INDEX(WBS_Dictionary!F$2:F$1212, MATCH(Table2[[#This Row],[WBS_ID]], Table26[WBS CODE],0)), "")) -> E540-30203-D245401 | W13: =IF(IFERROR(INDEX(WBS_Dictionary!G$2:G$1212, MATCH(Table2[[#This Row],[WBS_ID]], Table26[WBS CODE],0)), "") = "", "null", IFERROR(INDEX(WBS_Dictionary!G$2:G$1212, MATCH(Table2[[#This Row],[WBS_ID]], Table26[WBS CODE],0)), "")) -> E540-3020394-D245401 | X13: =IF(IFERROR(INDEX(WBS_Dictionary!H$2:H$1212, MATCH(Table2[[#This Row],[WBS_ID]], Table26[WBS CODE],0)), "") = "", "null", IFERROR(INDEX(WBS_Dictionary!H$2:H$1212, MATCH(Table2[[#This Row],[WBS_ID]], Table26[WBS CODE],0)), "")) -> E540-302039409-D245401 | Y13: =IF(IFERROR(INDEX(WBS_Dictionary!I$2:I$1212, MATCH(Table2[[#This Row],[WBS_ID]], Table26[WBS CODE],0)), "") = "", "null", IFERROR(INDEX(WBS_Dictionary!I$2:I$1212, MATCH(Table2[[#This Row],[WBS_ID]], Table26[WBS CODE],0)), "")) -> null | Z13: =IF(IFERROR(INDEX(WBS_Dictionary!J$2:J$1212, MATCH(Table2[[#This Row],[WBS_ID]], Table26[WBS CODE],0)), "") = "", "null", IFERROR(INDEX(WBS_Dictionary!J$2:J$1212, MATCH(Table2[[#This Row],[WBS_ID]], Table26[WBS CODE],0)), "")) -> Surface Facilities Cost | AA13: =IF(IFERROR(INDEX(WBS_Dictionary!K$2:K$1212, MATCH(Table2[[#This Row],[WBS_ID]], Table26[WBS CODE],0)), "") = "", "null", IFERROR(INDEX(WBS_Dictionary!K$2:K$1212, MATCH(Table2[[#This Row],[WBS_ID]], Table26[WBS CODE],0)), "")) -> Tie-in | AB13: =IF(IFERROR(INDEX(WBS_Dictionary!L$2:L$1212, MATCH(Table2[[#This Row],[WBS_ID]], Table26[WBS CODE],0)), "") = "", "null", IFERROR(INDEX(WBS_Dictionary!L$2:L$1212, MATCH(Table2[[#This Row],[WBS_ID]], Table26[WBS CODE],0)), "")) -> Construction | ... AE13: =IF(IFERROR(INDEX(WBS_Dictionary!O$2:O$1212, MATCH(Table2[[#This Row],[WBS_ID]], Table26[WBS CODE],0)), "") = "", "null", IFERROR(INDEX(WBS_Dictionary!O$2:O$1212, MATCH(Table2[[#This Row],[WBS_ID]], Table26[WBS CODE],0)), "")) -> Pad
A14: 13 | B14: 05 | C14: Tie In-Inst,HookUp&Pre-Comm Pad AWI3 | D14: E540-30203940963-D245401 | E14: D245401 | F14: 0 | G14: USD | H14: 0 | I14: USD | J14: 0 | K14: USD | L14: 11341.6 | M14: USD | N14: 143570.32 | O14: USD | P14: X | R14: STAR ENERGY | S14: Production | T14: REL AUC AVAC SETC // BUDG | U14: =IF(IFERROR(INDEX(WBS_Dictionary!E$2:E$1212, MATCH(Table2[[#This Row],[WBS_ID]], Table26[WBS CODE],0)), "") = "", "null", IFERROR(INDEX(WBS_Dictionary!E$2:E$1212, MATCH(Table2[[#This Row],[WBS_ID]], Table26[WBS CODE],0)), "")) -> E540-30-D245401 | V14: =IF(IFERROR(INDEX(WBS_Dictionary!F$2:F$1212, MATCH(Table2[[#This Row],[WBS_ID]], Table26[WBS CODE],0)), "") = "", "null", IFERROR(INDEX(WBS_Dictionary!F$2:F$1212, MATCH(Table2[[#This Row],[WBS_ID]], Table26[WBS CODE],0)), "")) -> E540-30203-D245401 | W14: =IF(IFERROR(INDEX(WBS_Dictionary!G$2:G$1212, MATCH(Table2[[#This Row],[WBS_ID]], Table26[WBS CODE],0)), "") = "", "null", IFERROR(INDEX(WBS_Dictionary!G$2:G$1212, MATCH(Table2[[#This Row],[WBS_ID]], Table26[WBS CODE],0)), "")) -> E540-3020394-D245401 | X14: =IF(IFERROR(INDEX(WBS_Dictionary!H$2:H$1212, MATCH(Table2[[#This Row],[WBS_ID]], Table26[WBS CODE],0)), "") = "", "null", IFERROR(INDEX(WBS_Dictionary!H$2:H$1212, MATCH(Table2[[#This Row],[WBS_ID]], Table26[WBS CODE],0)), "")) -> E540-302039409-D245401 | Y14: =IF(IFERROR(INDEX(WBS_Dictionary!I$2:I$1212, MATCH(Table2[[#This Row],[WBS_ID]], Table26[WBS CODE],0)), "") = "", "null", IFERROR(INDEX(WBS_Dictionary!I$2:I$1212, MATCH(Table2[[#This Row],[WBS_ID]], Table26[WBS CODE],0)), "")) -> E540-30203940963-D245401 | Z14: =IF(IFERROR(INDEX(WBS_Dictionary!J$2:J$1212, MATCH(Table2[[#This Row],[WBS_ID]], Table26[WBS CODE],0)), "") = "", "null", IFERROR(INDEX(WBS_Dictionary!J$2:J$1212, MATCH(Table2[[#This Row],[WBS_ID]], Table26[WBS CODE],0)), "")) -> Surface Facilities Cost | AA14: =IF(IFERROR(INDEX(WBS_Dictionary!K$2:K$1212, MATCH(Table2[[#This Row],[WBS_ID]], Table26[WBS CODE],0)), "") = "", "null", IFERROR(INDEX(WBS_Dictionary!K$2:K$1212, MATCH(Table2[[#This Row],[WBS_ID]], Table26[WBS CODE],0)), "")) -> Tie-in | AB14: =IF(IFERROR(INDEX(WBS_Dictionary!L$2:L$1212, MATCH(Table2[[#This Row],[WBS_ID]], Table26[WBS CODE],0)), "") = "", "null", IFERROR(INDEX(WBS_Dictionary!L$2:L$1212, MATCH(Table2[[#This Row],[WBS_ID]], Table26[WBS CODE],0)), "")) -> Construction | ... AE14: =IF(IFERROR(INDEX(WBS_Dictionary!O$2:O$1212, MATCH(Table2[[#This Row],[WBS_ID]], Table26[WBS CODE],0)), "") = "", "null", IFERROR(INDEX(WBS_Dictionary!O$2:O$1212, MATCH(Table2[[#This Row],[WBS_ID]], Table26[WBS CODE],0)), "")) -> Pad
A15: 14 | B15: 04 | C15: Tie In - Proc Pad AWI3 | D15: E540-302039408-D245401 | E15: D245401 | F15: 201428.97 | G15: USD | H15: 201428.97 | I15: USD | J15: 0 | K15: USD | L15: 7353.45 | M15: USD | N15: 158684.62 | O15: USD | P15: X | R15: STAR ENERGY | S15: Production | T15: REL BUDG ISBD AVAC // BUDG | U15: =IF(IFERROR(INDEX(WBS_Dictionary!E$2:E$1212, MATCH(Table2[[#This Row],[WBS_ID]], Table26[WBS CODE],0)), "") = "", "null", IFERROR(INDEX(WBS_Dictionary!E$2:E$1212, MATCH(Table2[[#This Row],[WBS_ID]], Table26[WBS CODE],0)), "")) -> E540-30-D245401 | V15: =IF(IFERROR(INDEX(WBS_Dictionary!F$2:F$1212, MATCH(Table2[[#This Row],[WBS_ID]], Table26[WBS CODE],0)), "") = "", "null", IFERROR(INDEX(WBS_Dictionary!F$2:F$1212, MATCH(Table2[[#This Row],[WBS_ID]], Table26[WBS CODE],0)), "")) -> E540-30203-D245401 | W15: =IF(IFERROR(INDEX(WBS_Dictionary!G$2:G$1212, MATCH(Table2[[#This Row],[WBS_ID]], Table26[WBS CODE],0)), "") = "", "null", IFERROR(INDEX(WBS_Dictionary!G$2:G$1212, MATCH(Table2[[#This Row],[WBS_ID]], Table26[WBS CODE],0)), "")) -> E540-3020394-D245401 | X15: =IF(IFERROR(INDEX(WBS_Dictionary!H$2:H$1212, MATCH(Table2[[#This Row],[WBS_ID]], Table26[WBS CODE],0)), "") = "", "null", IFERROR(INDEX(WBS_Dictionary!H$2:H$1212, MATCH(Table2[[#This Row],[WBS_ID]], Table26[WBS CODE],0)), "")) -> E540-302039408-D245401 | Y15: =IF(IFERROR(INDEX(WBS_Dictionary!I$2:I$1212, MATCH(Table2[[#This Row],[WBS_ID]], Table26[WBS CODE],0)), "") = "", "null", IFERROR(INDEX(WBS_Dictionary!I$2:I$1212, MATCH(Table2[[#This Row],[WBS_ID]], Table26[WBS CODE],0)), "")) -> null | Z15: =IF(IFERROR(INDEX(WBS_Dictionary!J$2:J$1212, MATCH(Table2[[#This Row],[WBS_ID]], Table26[WBS CODE],0)), "") = "", "null", IFERROR(INDEX(WBS_Dictionary!J$2:J$1212, MATCH(Table2[[#This Row],[WBS_ID]], Table26[WBS CODE],0)), "")) -> Surface Facilities Cost | AA15: =IF(IFERROR(INDEX(WBS_Dictionary!K$2:K$1212, MATCH(Table2[[#This Row],[WBS_ID]], Table26[WBS CODE],0)), "") = "", "null", IFERROR(INDEX(WBS_Dictionary!K$2:K$1212, MATCH(Table2[[#This Row],[WBS_ID]], Table26[WBS CODE],0)), "")) -> Tie-in | AB15: =IF(IFERROR(INDEX(WBS_Dictionary!L$2:L$1212, MATCH(Table2[[#This Row],[WBS_ID]], Table26[WBS CODE],0)), "") = "", "null", IFERROR(INDEX(WBS_Dictionary!L$2:L$1212, MATCH(Table2[[#This Row],[WBS_ID]], Table26[WBS CODE],0)), "")) -> Procurement | ... AE15: =IF(IFERROR(INDEX(WBS_Dictionary!O$2:O$1212, MATCH(Table2[[#This Row],[WBS_ID]], Table26[WBS CODE],0)), "") = "", "null", IFERROR(INDEX(WBS_Dictionary!O$2:O$1212, MATCH(Table2[[#This Row],[WBS_ID]], Table26[WBS CODE],0)), "")) -> Pad
... A76: 75 | B76: 05 | C76: Road & Pad Eng Pad AWI2 | D76: E540-30203830759-D245401 | E76: D245401 | F76: 0 | G76: USD | H76: 0 | I76: USD | J76: 0 | K76: USD | L76: 0 | M76: USD | N76: 24412.75 | O76: USD | P76: X | R76: STAR ENERGY | S76: Production | T76: REL AUC AVAC SETC // BUDG | U76: =IF(IFERROR(INDEX(WBS_Dictionary!E$2:E$1212, MATCH(Table2[[#This Row],[WBS_ID]], Table26[WBS CODE],0)), "") = "", "null", IFERROR(INDEX(WBS_Dictionary!E$2:E$1212, MATCH(Table2[[#This Row],[WBS_ID]], Table26[WBS CODE],0)), "")) -> E540-30-D245401 | V76: =IF(IFERROR(INDEX(WBS_Dictionary!F$2:F$1212, MATCH(Table2[[#This Row],[WBS_ID]], Table26[WBS CODE],0)), "") = "", "null", IFERROR(INDEX(WBS_Dictionary!F$2:F$1212, MATCH(Table2[[#This Row],[WBS_ID]], Table26[WBS CODE],0)), "")) -> E540-30203-D245401 | W76: =IF(IFERROR(INDEX(WBS_Dictionary!G$2:G$1212, MATCH(Table2[[#This Row],[WBS_ID]], Table26[WBS CODE],0)), "") = "", "null", IFERROR(INDEX(WBS_Dictionary!G$2:G$1212, MATCH(Table2[[#This Row],[WBS_ID]], Table26[WBS CODE],0)), "")) -> E540-3020383-D245401 | X76: =IF(IFERROR(INDEX(WBS_Dictionary!H$2:H$1212, MATCH(Table2[[#This Row],[WBS_ID]], Table26[WBS CODE],0)), "") = "", "null", IFERROR(INDEX(WBS_Dictionary!H$2:H$1212, MATCH(Table2[[#This Row],[WBS_ID]], Table26[WBS CODE],0)), "")) -> E540-302038307-D245401 | Y76: =IF(IFERROR(INDEX(WBS_Dictionary!I$2:I$1212, MATCH(Table2[[#This Row],[WBS_ID]], Table26[WBS CODE],0)), "") = "", "null", IFERROR(INDEX(WBS_Dictionary!I$2:I$1212, MATCH(Table2[[#This Row],[WBS_ID]], Table26[WBS CODE],0)), "")) -> E540-30203830759-D245401 | Z76: =IF(IFERROR(INDEX(WBS_Dictionary!J$2:J$1212, MATCH(Table2[[#This Row],[WBS_ID]], Table26[WBS CODE],0)), "") = "", "null", IFERROR(INDEX(WBS_Dictionary!J$2:J$1212, MATCH(Table2[[#This Row],[WBS_ID]], Table26[WBS CODE],0)), "")) -> Surface Facilities Cost | AA76: =IF(IFERROR(INDEX(WBS_Dictionary!K$2:K$1212, MATCH(Table2[[#This Row],[WBS_ID]], Table26[WBS CODE],0)), "") = "", "null", IFERROR(INDEX(WBS_Dictionary!K$2:K$1212, MATCH(Table2[[#This Row],[WBS_ID]], Table26[WBS CODE],0)), "")) -> Road & Pad | AB76: =IF(IFERROR(INDEX(WBS_Dictionary!L$2:L$1212, MATCH(Table2[[#This Row],[WBS_ID]], Table26[WBS CODE],0)), "") = "", "null", IFERROR(INDEX(WBS_Dictionary!L$2:L$1212, MATCH(Table2[[#This Row],[WBS_ID]], Table26[WBS CODE],0)), "")) -> Engineering | ... AE76: =IF(IFERROR(INDEX(WBS_Dictionary!O$2:O$1212, MATCH(Table2[[#This Row],[WBS_ID]], Table26[WBS CODE],0)), "") = "", "null", IFERROR(INDEX(WBS_Dictionary!O$2:O$1212, MATCH(Table2[[#This Row],[WBS_ID]], Table26[WBS CODE],0)), "")) -> Pad
A77: 76 | B77: 03 | C77: Conductor casing installation & material | D77: E540-3020374-D245401 | E77: D245401 | F77: 2987092.4 | G77: USD | H77: 2987092.4 | I77: USD | J77: 0 | K77: USD | L77: 0 | M77: USD | N77: 1843582.9 | O77: USD | Q77: X | R77: STAR ENERGY | S77: Production | T77: REL BUDG AVAC // BUDG | U77: =IF(IFERROR(INDEX(WBS_Dictionary!E$2:E$1212, MATCH(Table2[[#This Row],[WBS_ID]], Table26[WBS CODE],0)), "") = "", "null", IFERROR(INDEX(WBS_Dictionary!E$2:E$1212, MATCH(Table2[[#This Row],[WBS_ID]], Table26[WBS CODE],0)), "")) -> E540-30-D245401 | V77: =IF(IFERROR(INDEX(WBS_Dictionary!F$2:F$1212, MATCH(Table2[[#This Row],[WBS_ID]], Table26[WBS CODE],0)), "") = "", "null", IFERROR(INDEX(WBS_Dictionary!F$2:F$1212, MATCH(Table2[[#This Row],[WBS_ID]], Table26[WBS CODE],0)), "")) -> E540-30203-D245401 | W77: =IF(IFERROR(INDEX(WBS_Dictionary!G$2:G$1212, MATCH(Table2[[#This Row],[WBS_ID]], Table26[WBS CODE],0)), "") = "", "null", IFERROR(INDEX(WBS_Dictionary!G$2:G$1212, MATCH(Table2[[#This Row],[WBS_ID]], Table26[WBS CODE],0)), "")) -> E540-3020374-D245401 | X77: =IF(IFERROR(INDEX(WBS_Dictionary!H$2:H$1212, MATCH(Table2[[#This Row],[WBS_ID]], Table26[WBS CODE],0)), "") = "", "null", IFERROR(INDEX(WBS_Dictionary!H$2:H$1212, MATCH(Table2[[#This Row],[WBS_ID]], Table26[WBS CODE],0)), "")) -> null | Y77: =IF(IFERROR(INDEX(WBS_Dictionary!I$2:I$1212, MATCH(Table2[[#This Row],[WBS_ID]], Table26[WBS CODE],0)), "") = "", "null", IFERROR(INDEX(WBS_Dictionary!I$2:I$1212, MATCH(Table2[[#This Row],[WBS_ID]], Table26[WBS CODE],0)), "")) -> null | Z77: =IF(IFERROR(INDEX(WBS_Dictionary!J$2:J$1212, MATCH(Table2[[#This Row],[WBS_ID]], Table26[WBS CODE],0)), "") = "", "null", IFERROR(INDEX(WBS_Dictionary!J$2:J$1212, MATCH(Table2[[#This Row],[WBS_ID]], Table26[WBS CODE],0)), "")) -> Surface Facilities Cost | AA77: =IF(IFERROR(INDEX(WBS_Dictionary!K$2:K$1212, MATCH(Table2[[#This Row],[WBS_ID]], Table26[WBS CODE],0)), "") = "", "null", IFERROR(INDEX(WBS_Dictionary!K$2:K$1212, MATCH(Table2[[#This Row],[WBS_ID]], Table26[WBS CODE],0)), "")) -> Conductor Casing Installation & Material | AB77: =IF(IFERROR(INDEX(WBS_Dictionary!L$2:L$1212, MATCH(Table2[[#This Row],[WBS_ID]], Table26[WBS CODE],0)), "") = "", "null", IFERROR(INDEX(WBS_Dictionary!L$2:L$1212, MATCH(Table2[[#This Row],[WBS_ID]], Table26[WBS CODE],0)), "")) -> null | ... AE77: =IF(IFERROR(INDEX(WBS_Dictionary!O$2:O$1212, MATCH(Table2[[#This Row],[WBS_ID]], Table26[WBS CODE],0)), "") = "", "null", IFERROR(INDEX(WBS_Dictionary!O$2:O$1212, MATCH(Table2[[#This Row],[WBS_ID]], Table26[WBS CODE],0)), "")) -> null
