Workbook

Sheet Sheet7
B4: 17.5 | C4: 12.5 | D4: =B4/C4 -> 1.4
D36: 1.4
D37: 1.75
D38: =D36/D37 -> 0.8

Sheet Charts

Sheet $_day

Sheet $_ft

Sheet Sheet6
B46: Bagaimana menjawab pertanyaan "bayar mahal tapi lancar"?

Sheet DashBoard.Tab.Template
B2: Asset | C2: Asset_Label | D2: Campaign | E2: Camp_Label | F2: Well | G2: Well_Label | H2: No of Wells Drilled | I2: Campaign Cost USD mn | J2: Well Cost USD mn | K2: Drilling Shared Cost USD mn | L2: Support Cost USD | M2: Surface Facilities Cost USD | N2: Campaign Cost per Well USD | O2: Actual Total Depth ft MD | P2: Drilling Duration days
B3: Darajat | C3: Darajat | D3: DRJ - 2019 | E3: DRJ - 2019 | F3: DRJ-44OH | G3: DRJ-44OH | H3: =COUNTIFS(tab_DB_Temp[Campaign], tab_DB_Temp[[#This Row],[Campaign]])*1 -> 5 | I3: {=SUMPRODUCT(Table1[Actual Cost USD]*(Table1[Campaign]=tab_DB_Temp[[#This Row],[Campaign]]))/1000000} -> 42.003384 | J3: {=SUMPRODUCT(Table1[Actual Cost USD]*(Table1[Well]=tab_DB_Temp[[#This Row],[Well]])*(Table1[Level 3]="Well Cost"))/1000000} -> 4.2156197 | K3: {=(SUMPRODUCT(Table1[Actual Cost USD]*(Table1[Campaign]=tab_DB_Temp[[#This Row],[Campaign]])*(Table1[Level 2]="Drilling Cost")*(Table1[Level 3]<>"Well Cost")) + SUMPRODUCT(Table1[Actual Cost USD]*(Table1[Campaign]=tab_DB_Temp[[#This Row],[Campaign]])*(Table1[Level 3]="Well Cost")*(Table1[Well]="General")))/tab_DB_Temp[[#This Row],[No of Wells Drilled]]/1000000} -> 0.8960439 | L3: {=SUMPRODUCT(Table1[Actual Cost USD]*(Table1[Level 2]="Support Cost")*(Table1[Campaign]=tab_DB_Temp[[#This Row],[Campaign]]))/tab_DB_Temp[[#This Row],[No of Wells Drilled]]/1000000} -> 0.46408771 | M3: {=SUMPRODUCT(Table1[Actual Cost USD]*(Table1[Level 2]="Surface Facilities Cost")*(Table1[Campaign]=tab_DB_Temp[[#This Row],[Campaign]]))/tab_DB_Temp[[#This Row],[No of Wells Drilled]]/1000000} -> 1.6157892 | N3: =SUM(tab_DB_Temp[[#This Row],[Well Cost USD mn]:[Surface Facilities Cost USD]])*1 -> 7.1915405 | O3: =IFERROR(INDEX(Table2[Actual depth, ft MD], MATCH(tab_DB_Temp[[#This Row],[Well]], Table2[Well Name Actual], 0))*1, 0) -> 0 | P3: =IFERROR(INDEX(Table2[Drilling Duration, days equivalent], MATCH(tab_DB_Temp[[#This Row],[Well]], Table2[Well Name Actual],0))*1, 0) -> 0
B4: Darajat | C4: Darajat | D4: DRJ - 2019 | E4: DRJ - 2019 | F4: DRJ-45OH | G4: DRJ-45OH | H4: =COUNTIFS(tab_DB_Temp[Campaign], tab_DB_Temp[[#This Row],[Campaign]])*1 -> 5 | I4: {=SUMPRODUCT(Table1[Actual Cost USD]*(Table1[Campaign]=tab_DB_Temp[[#This Row],[Campaign]]))/1000000} -> 42.003384 | J4: {=SUMPRODUCT(Table1[Actual Cost USD]*(Table1[Well]=tab_DB_Temp[[#This Row],[Well]])*(Table1[Level 3]="Well Cost"))/1000000} -> 6.556112 | K4: {=(SUMPRODUCT(Table1[Actual Cost USD]*(Table1[Campaign]=tab_DB_Temp[[#This Row],[Campaign]])*(Table1[Level 2]="Drilling Cost")*(Table1[Level 3]<>"Well Cost")) + SUMPRODUCT(Table1[Actual Cost USD]*(Table1[Campaign]=tab_DB_Temp[[#This Row],[Campaign]])*(Table1[Level 3]="Well Cost")*(Table1[Well]="General")))/tab_DB_Temp[[#This Row],[No of Wells Drilled]]/1000000} -> 0.8960439 | L4: {=SUMPRODUCT(Table1[Actual Cost USD]*(Table1[Level 2]="Support Cost")*(Table1[Campaign]=tab_DB_Temp[[#This Row],[Campaign]]))/tab_DB_Temp[[#This Row],[No of Wells Drilled]]/1000000} -> 0.46408771 | M4: {=SUMPRODUCT(Table1[Actual Cost USD]*(Table1[Level 2]="Surface Facilities Cost")*(Table1[Campaign]=tab_DB_Temp[[#This Row],[Campaign]]))/tab_DB_Temp[[#This Row],[No of Wells Drilled]]/1000000} -> 1.6157892 | N4: =SUM(tab_DB_Temp[[#This Row],[Well Cost USD mn]:[Surface Facilities Cost USD]])*1 -> 9.5320328 | O4: =IFERROR(INDEX(Table2[Actual depth, ft MD], MATCH(tab_DB_Temp[[#This Row],[Well]], Table2[Well Name Actual], 0))*1, 0) -> 0 | P4: =IFERROR(INDEX(Table2[Drilling Duration, days equivalent], MATCH(tab_DB_Temp[[#This Row],[Well]], Table2[Well Name Actual],0))*1, 0) -> 0
B5: Darajat | C5: Darajat | D5: DRJ - 2019 | E5: DRJ - 2019 | F5: DRJ-46OH | G5: DRJ-46OH | H5: =COUNTIFS(tab_DB_Temp[Campaign], tab_DB_Temp[[#This Row],[Campaign]])*1 -> 5 | I5: {=SUMPRODUCT(Table1[Actual Cost USD]*(Table1[Campaign]=tab_DB_Temp[[#This Row],[Campaign]]))/1000000} -> 42.003384 | J5: {=SUMPRODUCT(Table1[Actual Cost USD]*(Table1[Well]=tab_DB_Temp[[#This Row],[Well]])*(Table1[Level 3]="Well Cost"))/1000000} -> 5.9691517 | K5: {=(SUMPRODUCT(Table1[Actual Cost USD]*(Table1[Campaign]=tab_DB_Temp[[#This Row],[Campaign]])*(Table1[Level 2]="Drilling Cost")*(Table1[Level 3]<>"Well Cost")) + SUMPRODUCT(Table1[Actual Cost USD]*(Table1[Campaign]=tab_DB_Temp[[#This Row],[Campaign]])*(Table1[Level 3]="Well Cost")*(Table1[Well]="General")))/tab_DB_Temp[[#This Row],[No of Wells Drilled]]/1000000} -> 0.8960439 | L5: {=SUMPRODUCT(Table1[Actual Cost USD]*(Table1[Level 2]="Support Cost")*(Table1[Campaign]=tab_DB_Temp[[#This Row],[Campaign]]))/tab_DB_Temp[[#This Row],[No of Wells Drilled]]/1000000} -> 0.46408771 | M5: {=SUMPRODUCT(Table1[Actual Cost USD]*(Table1[Level 2]="Surface Facilities Cost")*(Table1[Campaign]=tab_DB_Temp[[#This Row],[Campaign]]))/tab_DB_Temp[[#This Row],[No of Wells Drilled]]/1000000} -> 1.6157892 | N5: =SUM(tab_DB_Temp[[#This Row],[Well Cost USD mn]:[Surface Facilities Cost USD]])*1 -> 8.9450725 | O5: =IFERROR(INDEX(Table2[Actual depth, ft MD], MATCH(tab_DB_Temp[[#This Row],[Well]], Table2[Well Name Actual], 0))*1, 0) -> 0 | P5: =IFERROR(INDEX(Table2[Drilling Duration, days equivalent], MATCH(tab_DB_Temp[[#This Row],[Well]], Table2[Well Name Actual],0))*1, 0) -> 0
B6: Darajat | C6: Darajat | D6: DRJ - 2019 | E6: DRJ - 2019 | F6: DRJ-47OH | G6: DRJ-47OH | H6: =COUNTIFS(tab_DB_Temp[Campaign], tab_DB_Temp[[#This Row],[Campaign]])*1 -> 5 | I6: {=SUMPRODUCT(Table1[Actual Cost USD]*(Table1[Campaign]=tab_DB_Temp[[#This Row],[Campaign]]))/1000000} -> 42.003384 | J6: {=SUMPRODUCT(Table1[Actual Cost USD]*(Table1[Well]=tab_DB_Temp[[#This Row],[Well]])*(Table1[Level 3]="Well Cost"))/1000000} -> 4.803795 | K6: {=(SUMPRODUCT(Table1[Actual Cost USD]*(Table1[Campaign]=tab_DB_Temp[[#This Row],[Campaign]])*(Table1[Level 2]="Drilling Cost")*(Table1[Level 3]<>"Well Cost")) + SUMPRODUCT(Table1[Actual Cost USD]*(Table1[Campaign]=tab_DB_Temp[[#This Row],[Campaign]])*(Table1[Level 3]="Well Cost")*(Table1[Well]="General")))/tab_DB_Temp[[#This Row],[No of Wells Drilled]]/1000000} -> 0.8960439 | L6: {=SUMPRODUCT(Table1[Actual Cost USD]*(Table1[Level 2]="Support Cost")*(Table1[Campaign]=tab_DB_Temp[[#This Row],[Campaign]]))/tab_DB_Temp[[#This Row],[No of Wells Drilled]]/1000000} -> 0.46408771 | M6: {=SUMPRODUCT(Table1[Actual Cost USD]*(Table1[Level 2]="Surface Facilities Cost")*(Table1[Campaign]=tab_DB_Temp[[#This Row],[Campaign]]))/tab_DB_Temp[[#This Row],[No of Wells Drilled]]/1000000} -> 1.6157892 | N6: =SUM(tab_DB_Temp[[#This Row],[Well Cost USD mn]:[Surface Facilities Cost USD]])*1 -> 7.7797158 | O6: =IFERROR(INDEX(Table2[Actual depth, ft MD], MATCH(tab_DB_Temp[[#This Row],[Well]], Table2[Well Name Actual], 0))*1, 0) -> 0 | P6: =IFERROR(INDEX(Table2[Drilling Duration, days equivalent], MATCH(tab_DB_Temp[[#This Row],[Well]], Table2[Well Name Actual],0))*1, 0) -> 0
B7: Darajat | C7: Darajat | D7: DRJ - 2019 | E7: DRJ - 2019 | F7: DRJ-48 | G7: DRJ-48 | H7: =COUNTIFS(tab_DB_Temp[Campaign], tab_DB_Temp[[#This Row],[Campaign]])*1 -> 5 | I7: {=SUMPRODUCT(Table1[Actual Cost USD]*(Table1[Campaign]=tab_DB_Temp[[#This Row],[Campaign]]))/1000000} -> 42.003384 | J7: {=SUMPRODUCT(Table1[Actual Cost USD]*(Table1[Well]=tab_DB_Temp[[#This Row],[Well]])*(Table1[Level 3]="Well Cost"))/1000000} -> 5.5791018 | K7: {=(SUMPRODUCT(Table1[Actual Cost USD]*(Table1[Campaign]=tab_DB_Temp[[#This Row],[Campaign]])*(Table1[Level 2]="Drilling Cost")*(Table1[Level 3]<>"Well Cost")) + SUMPRODUCT(Table1[Actual Cost USD]*(Table1[Campaign]=tab_DB_Temp[[#This Row],[Campaign]])*(Table1[Level 3]="Well Cost")*(Table1[Well]="General")))/tab_DB_Temp[[#This Row],[No of Wells Drilled]]/1000000} -> 0.8960439 | L7: {=SUMPRODUCT(Table1[Actual Cost USD]*(Table1[Level 2]="Support Cost")*(Table1[Campaign]=tab_DB_Temp[[#This Row],[Campaign]]))/tab_DB_Temp[[#This Row],[No of Wells Drilled]]/1000000} -> 0.46408771 | M7: {=SUMPRODUCT(Table1[Actual Cost USD]*(Table1[Level 2]="Surface Facilities Cost")*(Table1[Campaign]=tab_DB_Temp[[#This Row],[Campaign]]))/tab_DB_Temp[[#This Row],[No of Wells Drilled]]/1000000} -> 1.6157892 | N7: =SUM(tab_DB_Temp[[#This Row],[Well Cost USD mn]:[Surface Facilities Cost USD]])*1 -> 8.5550226 | O7: =IFERROR(INDEX(Table2[Actual depth, ft MD], MATCH(tab_DB_Temp[[#This Row],[Well]], Table2[Well Name Actual], 0))*1, 0) -> 5399.5 | P7: =IFERROR(INDEX(Table2[Drilling Duration, days equivalent], MATCH(tab_DB_Temp[[#This Row],[Well]], Table2[Well Name Actual],0))*1, 0) -> 21.479167
B8: Darajat | C8: Darajat | D8: DRJ - 2022 | E8: DRJ - 2022 | F8: DRJ-38RD | G8: DRJ-38RD | H8: =COUNTIFS(tab_DB_Temp[Campaign], tab_DB_Temp[[#This Row],[Campaign]])*1 -> 5 | I8: {=SUMPRODUCT(Table1[Actual Cost USD]*(Table1[Campaign]=tab_DB_Temp[[#This Row],[Campaign]]))/1000000} -> 30.669525 | J8: {=SUMPRODUCT(Table1[Actual Cost USD]*(Table1[Well]=tab_DB_Temp[[#This Row],[Well]])*(Table1[Level 3]="Well Cost"))/1000000} -> 3.9122157 | K8: {=(SUMPRODUCT(Table1[Actual Cost USD]*(Table1[Campaign]=tab_DB_Temp[[#This Row],[Campaign]])*(Table1[Level 2]="Drilling Cost")*(Table1[Level 3]<>"Well Cost")) + SUMPRODUCT(Table1[Actual Cost USD]*(Table1[Campaign]=tab_DB_Temp[[#This Row],[Campaign]])*(Table1[Level 3]="Well Cost")*(Table1[Well]="General")))/tab_DB_Temp[[#This Row],[No of Wells Drilled]]/1000000} -> 0.91247612 | L8: {=SUMPRODUCT(Table1[Actual Cost USD]*(Table1[Level 2]="Support Cost")*(Table1[Campaign]=tab_DB_Temp[[#This Row],[Campaign]]))/tab_DB_Temp[[#This Row],[No of Wells Drilled]]/1000000} -> 0.38913332 | M8: {=SUMPRODUCT(Table1[Actual Cost USD]*(Table1[Level 2]="Surface Facilities Cost")*(Table1[Campaign]=tab_DB_Temp[[#This Row],[Campaign]]))/tab_DB_Temp[[#This Row],[No of Wells Drilled]]/1000000} -> 0.73877073 | N8: =SUM(tab_DB_Temp[[#This Row],[Well Cost USD mn]:[Surface Facilities Cost USD]])*1 -> 5.9525959 | O8: =IFERROR(INDEX(Table2[Actual depth, ft MD], MATCH(tab_DB_Temp[[#This Row],[Well]], Table2[Well Name Actual], 0))*1, 0) -> 6748 | P8: =IFERROR(INDEX(Table2[Drilling Duration, days equivalent], MATCH(tab_DB_Temp[[#This Row],[Well]], Table2[Well Name Actual],0))*1, 0) -> 30
B9: Darajat | C9: Darajat | D9: DRJ - 2022 | E9: DRJ - 2022 | F9: DRJ-49OH | G9: DRJ-49OH | H9: =COUNTIFS(tab_DB_Temp[Campaign], tab_DB_Temp[[#This Row],[Campaign]])*1 -> 5 | I9: {=SUMPRODUCT(Table1[Actual Cost USD]*(Table1[Campaign]=tab_DB_Temp[[#This Row],[Campaign]]))/1000000} -> 30.669525 | J9: {=SUMPRODUCT(Table1[Actual Cost USD]*(Table1[Well]=tab_DB_Temp[[#This Row],[Well]])*(Table1[Level 3]="Well Cost"))/1000000} -> 4.7828762 | K9: {=(SUMPRODUCT(Table1[Actual Cost USD]*(Table1[Campaign]=tab_DB_Temp[[#This Row],[Campaign]])*(Table1[Level 2]="Drilling Cost")*(Table1[Level 3]<>"Well Cost")) + SUMPRODUCT(Table1[Actual Cost USD]*(Table1[Campaign]=tab_DB_Temp[[#This Row],[Campaign]])*(Table1[Level 3]="Well Cost")*(Table1[Well]="General")))/tab_DB_Temp[[#This Row],[No of Wells Drilled]]/1000000} -> 0.91247612 | L9: {=SUMPRODUCT(Table1[Actual Cost USD]*(Table1[Level 2]="Support Cost")*(Table1[Campaign]=tab_DB_Temp[[#This Row],[Campaign]]))/tab_DB_Temp[[#This Row],[No of Wells Drilled]]/1000000} -> 0.38913332 | M9: {=SUMPRODUCT(Table1[Actual Cost USD]*(Table1[Level 2]="Surface Facilities Cost")*(Table1[Campaign]=tab_DB_Temp[[#This Row],[Campaign]]))/tab_DB_Temp[[#This Row],[No of Wells Drilled]]/1000000} -> 0.73877073 | N9: =SUM(tab_DB_Temp[[#This Row],[Well Cost USD mn]:[Surface Facilities Cost USD]])*1 -> 6.8232564 | O9: =IFERROR(INDEX(Table2[Actual depth, ft MD], MATCH(tab_DB_Temp[[#This Row],[Well]], Table2[Well Name Actual], 0))*1, 0) -> 0 | P9: =IFERROR(INDEX(Table2[Drilling Duration, days equivalent], MATCH(tab_DB_Temp[[#This Row],[Well]], Table2[Well Name Actual],0))*1, 0) -> 0
B10: Darajat | C10: Darajat | D10: DRJ - 2022 | E10: DRJ - 2022 | F10: DRJ-50OH | G10: DRJ-50OH | H10: =COUNTIFS(tab_DB_Temp[Campaign], tab_DB_Temp[[#This Row],[Campaign]])*1 -> 5 | I10: {=SUMPRODUCT(Table1[Actual Cost USD]*(Table1[Campaign]=tab_DB_Temp[[#This Row],[Campaign]]))/1000000} -> 30.669525 | J10: {=SUMPRODUCT(Table1[Actual Cost USD]*(Table1[Well]=tab_DB_Temp[[#This Row],[Well]])*(Table1[Level 3]="Well Cost"))/1000000} -> 4.0668032 | K10: {=(SUMPRODUCT(Table1[Actual Cost USD]*(Table1[Campaign]=tab_DB_Temp[[#This Row],[Campaign]])*(Table1[Level 2]="Drilling Cost")*(Table1[Level 3]<>"Well Cost")) + SUMPRODUCT(Table1[Actual Cost USD]*(Table1[Campaign]=tab_DB_Temp[[#This Row],[Campaign]])*(Table1[Level 3]="Well Cost")*(Table1[Well]="General")))/tab_DB_Temp[[#This Row],[No of Wells Drilled]]/1000000} -> 0.91247612 | L10: {=SUMPRODUCT(Table1[Actual Cost USD]*(Table1[Level 2]="Support Cost")*(Table1[Campaign]=tab_DB_Temp[[#This Row],[Campaign]]))/tab_DB_Temp[[#This Row],[No of Wells Drilled]]/1000000} -> 0.38913332 | M10: {=SUMPRODUCT(Table1[Actual Cost USD]*(Table1[Level 2]="Surface Facilities Cost")*(Table1[Campaign]=tab_DB_Temp[[#This Row],[Campaign]]))/tab_DB_Temp[[#This Row],[No of Wells Drilled]]/1000000} -> 0.73877073 | N10: =SUM(tab_DB_Temp[[#This Row],[Well Cost USD mn]:[Surface Facilities Cost USD]])*1 -> 6.1071834 | O10: =IFERROR(INDEX(Table2[Actual depth, ft MD], MATCH(tab_DB_Temp[[#This Row],[Well]], Table2[Well Name Actual], 0))*1, 0) -> 0 | P10: =IFERROR(INDEX(Table2[Drilling Duration, days equivalent], MATCH(tab_DB_Temp[[#This Row],[Well]], Table2[Well Name Actual],0))*1, 0) -> 0
B11: Darajat | C11: Darajat | D11: DRJ - 2022 | E11: DRJ - 2022 | F11: DRJ-51OH | G11: DRJ-51OH | H11: =COUNTIFS(tab_DB_Temp[Campaign], tab_DB_Temp[[#This Row],[Campaign]])*1 -> 5 | I11: {=SUMPRODUCT(Table1[Actual Cost USD]*(Table1[Campaign]=tab_DB_Temp[[#This Row],[Campaign]]))/1000000} -> 30.669525 | J11: {=SUMPRODUCT(Table1[Actual Cost USD]*(Table1[Well]=tab_DB_Temp[[#This Row],[Well]])*(Table1[Level 3]="Well Cost"))/1000000} -> 4.1984832 | K11: {=(SUMPRODUCT(Table1[Actual Cost USD]*(Table1[Campaign]=tab_DB_Temp[[#This Row],[Campaign]])*(Table1[Level 2]="Drilling Cost")*(Table1[Level 3]<>"Well Cost")) + SUMPRODUCT(Table1[Actual Cost USD]*(Table1[Campaign]=tab_DB_Temp[[#This Row],[Campaign]])*(Table1[Level 3]="Well Cost")*(Table1[Well]="General")))/tab_DB_Temp[[#This Row],[No of Wells Drilled]]/1000000} -> 0.91247612 | L11: {=SUMPRODUCT(Table1[Actual Cost USD]*(Table1[Level 2]="Support Cost")*(Table1[Campaign]=tab_DB_Temp[[#This Row],[Campaign]]))/tab_DB_Temp[[#This Row],[No of Wells Drilled]]/1000000} -> 0.38913332 | M11: {=SUMPRODUCT(Table1[Actual Cost USD]*(Table1[Level 2]="Surface Facilities Cost")*(Table1[Campaign]=tab_DB_Temp[[#This Row],[Campaign]]))/tab_DB_Temp[[#This Row],[No of Wells Drilled]]/1000000} -> 0.73877073 | N11: =SUM(tab_DB_Temp[[#This Row],[Well Cost USD mn]:[Surface Facilities Cost USD]])*1 -> 6.2388634 | O11: =IFERROR(INDEX(Table2[Actual depth, ft MD], MATCH(tab_DB_Temp[[#This Row],[Well]], Table2[Well Name Actual], 0))*1, 0) -> 0 | P11: =IFERROR(INDEX(Table2[Drilling Duration, days equivalent], MATCH(tab_DB_Temp[[#This Row],[Well]], Table2[Well Name Actual],0))*1, 0) -> 0
B12: Darajat | C12: Darajat | D12: DRJ - 2022 | E12: DRJ - 2022 | F12: DRJ-52OH | G12: DRJ-52OH | H12: =COUNTIFS(tab_DB_Temp[Campaign], tab_DB_Temp[[#This Row],[Campaign]])*1 -> 5 | I12: {=SUMPRODUCT(Table1[Actual Cost USD]*(Table1[Campaign]=tab_DB_Temp[[#This Row],[Campaign]]))/1000000} -> 30.669525 | J12: {=SUMPRODUCT(Table1[Actual Cost USD]*(Table1[Well]=tab_DB_Temp[[#This Row],[Well]])*(Table1[Level 3]="Well Cost"))/1000000} -> 3.5072457 | K12: {=(SUMPRODUCT(Table1[Actual Cost USD]*(Table1[Campaign]=tab_DB_Temp[[#This Row],[Campaign]])*(Table1[Level 2]="Drilling Cost")*(Table1[Level 3]<>"Well Cost")) + SUMPRODUCT(Table1[Actual Cost USD]*(Table1[Campaign]=tab_DB_Temp[[#This Row],[Campaign]])*(Table1[Level 3]="Well Cost")*(Table1[Well]="General")))/tab_DB_Temp[[#This Row],[No of Wells Drilled]]/1000000} -> 0.91247612 | L12: {=SUMPRODUCT(Table1[Actual Cost USD]*(Table1[Level 2]="Support Cost")*(Table1[Campaign]=tab_DB_Temp[[#This Row],[Campaign]]))/tab_DB_Temp[[#This Row],[No of Wells Drilled]]/1000000} -> 0.38913332 | M12: {=SUMPRODUCT(Table1[Actual Cost USD]*(Table1[Level 2]="Surface Facilities Cost")*(Table1[Campaign]=tab_DB_Temp[[#This Row],[Campaign]]))/tab_DB_Temp[[#This Row],[No of Wells Drilled]]/1000000} -> 0.73877073 | N12: =SUM(tab_DB_Temp[[#This Row],[Well Cost USD mn]:[Surface Facilities Cost USD]])*1 -> 5.5476258 | O12: =IFERROR(INDEX(Table2[Actual depth, ft MD], MATCH(tab_DB_Temp[[#This Row],[Well]], Table2[Well Name Actual], 0))*1, 0) -> 0 | P12: =IFERROR(INDEX(Table2[Drilling Duration, days equivalent], MATCH(tab_DB_Temp[[#This Row],[Well]], Table2[Well Name Actual],0))*1, 0) -> 0
B13: Darajat | C13: Darajat | D13: DRJ - 2024 | E13: DRJ - 2024 | F13: DRJ-53 | G13: DRJ-53 | H13: =COUNTIFS(tab_DB_Temp[Campaign], tab_DB_Temp[[#This Row],[Campaign]])*1 -> 5 | I13: {=SUMPRODUCT(Table1[Actual Cost USD]*(Table1[Campaign]=tab_DB_Temp[[#This Row],[Campaign]]))/1000000} -> 37.36711 | J13: {=SUMPRODUCT(Table1[Actual Cost USD]*(Table1[Well]=tab_DB_Temp[[#This Row],[Well]])*(Table1[Level 3]="Well Cost"))/1000000} -> 3.6095736 | K13: {=(SUMPRODUCT(Table1[Actual Cost USD]*(Table1[Campaign]=tab_DB_Temp[[#This Row],[Campaign]])*(Table1[Level 2]="Drilling Cost")*(Table1[Level 3]<>"Well Cost")) + SUMPRODUCT(Table1[Actual Cost USD]*(Table1[Campaign]=tab_DB_Temp[[#This Row],[Campaign]])*(Table1[Level 3]="Well Cost")*(Table1[Well]="General")))/tab_DB_Temp[[#This Row],[No of Wells Drilled]]/1000000} -> 1.0340317 | L13: {=SUMPRODUCT(Table1[Actual Cost USD]*(Table1[Level 2]="Support Cost")*(Table1[Campaign]=tab_DB_Temp[[#This Row],[Campaign]]))/tab_DB_Temp[[#This Row],[No of Wells Drilled]]/1000000} -> 0.38862086 | M13: {=SUMPRODUCT(Table1[Actual Cost USD]*(Table1[Level 2]="Surface Facilities Cost")*(Table1[Campaign]=tab_DB_Temp[[#This Row],[Campaign]]))/tab_DB_Temp[[#This Row],[No of Wells Drilled]]/1000000} -> 1.1211599 | N13: =SUM(tab_DB_Temp[[#This Row],[Well Cost USD mn]:[Surface Facilities Cost USD]])*1 -> 6.153386 | O13: =IFERROR(INDEX(Table2[Actual depth, ft MD], MATCH(tab_DB_Temp[[#This Row],[Well]], Table2[Well Name Actual], 0))*1, 0) -> 6500 | P13: =IFERROR(INDEX(Table2[Drilling Duration, days equivalent], MATCH(tab_DB_Temp[[#This Row],[Well]], Table2[Well Name Actual],0))*1, 0) -> 22.770833
B14: Darajat | C14: Darajat | D14: DRJ - 2024 | E14: DRJ - 2024 | F14: DRJ-54 | G14: DRJ-54 | H14: =COUNTIFS(tab_DB_Temp[Campaign], tab_DB_Temp[[#This Row],[Campaign]])*1 -> 5 | I14: {=SUMPRODUCT(Table1[Actual Cost USD]*(Table1[Campaign]=tab_DB_Temp[[#This Row],[Campaign]]))/1000000} -> 37.36711 | J14: {=SUMPRODUCT(Table1[Actual Cost USD]*(Table1[Well]=tab_DB_Temp[[#This Row],[Well]])*(Table1[Level 3]="Well Cost"))/1000000} -> 5.1895546 | K14: {=(SUMPRODUCT(Table1[Actual Cost USD]*(Table1[Campaign]=tab_DB_Temp[[#This Row],[Campaign]])*(Table1[Level 2]="Drilling Cost")*(Table1[Level 3]<>"Well Cost")) + SUMPRODUCT(Table1[Actual Cost USD]*(Table1[Campaign]=tab_DB_Temp[[#This Row],[Campaign]])*(Table1[Level 3]="Well Cost")*(Table1[Well]="General")))/tab_DB_Temp[[#This Row],[No of Wells Drilled]]/1000000} -> 1.0340317 | L14: {=SUMPRODUCT(Table1[Actual Cost USD]*(Table1[Level 2]="Support Cost")*(Table1[Campaign]=tab_DB_Temp[[#This Row],[Campaign]]))/tab_DB_Temp[[#This Row],[No of Wells Drilled]]/1000000} -> 0.38862086 | M14: {=SUMPRODUCT(Table1[Actual Cost USD]*(Table1[Level 2]="Surface Facilities Cost")*(Table1[Campaign]=tab_DB_Temp[[#This Row],[Campaign]]))/tab_DB_Temp[[#This Row],[No of Wells Drilled]]/1000000} -> 1.1211599 | N14: =SUM(tab_DB_Temp[[#This Row],[Well Cost USD mn]:[Surface Facilities Cost USD]])*1 -> 7.733367 | O14: =IFERROR(INDEX(Table2[Actual depth, ft MD], MATCH(tab_DB_Temp[[#This Row],[Well]], Table2[Well Name Actual], 0))*1, 0) -> 6014 | P14: =IFERROR(INDEX(Table2[Drilling Duration, days equivalent], MATCH(tab_DB_Temp[[#This Row],[Well]], Table2[Well Name Actual],0))*1, 0) -> 29.6875
... B41: Wayang Windu | C41: Wayang Windu | D41: WW - 2021 | E41: WW - 2021 | F41: WWA-9 | G41: WWA-9 | H41: =COUNTIFS(tab_DB_Temp[Campaign], tab_DB_Temp[[#This Row],[Campaign]])*1 -> 6 | I41: {=SUMPRODUCT(Table1[Actual Cost USD]*(Table1[Campaign]=tab_DB_Temp[[#This Row],[Campaign]]))/1000000} -> 27.074998 | J41: {=SUMPRODUCT(Table1[Actual Cost USD]*(Table1[Well]=tab_DB_Temp[[#This Row],[Well]])*(Table1[Level 3]="Well Cost"))/1000000} -> 2.9031327 | K41: {=(SUMPRODUCT(Table1[Actual Cost USD]*(Table1[Campaign]=tab_DB_Temp[[#This Row],[Campaign]])*(Table1[Level 2]="Drilling Cost")*(Table1[Level 3]<>"Well Cost")) + SUMPRODUCT(Table1[Actual Cost USD]*(Table1[Campaign]=tab_DB_Temp[[#This Row],[Campaign]])*(Table1[Level 3]="Well Cost")*(Table1[Well]="General")))/tab_DB_Temp[[#This Row],[No of Wells Drilled]]/1000000} -> 0.77751374 | L41: {=SUMPRODUCT(Table1[Actual Cost USD]*(Table1[Level 2]="Support Cost")*(Table1[Campaign]=tab_DB_Temp[[#This Row],[Campaign]]))/tab_DB_Temp[[#This Row],[No of Wells Drilled]]/1000000} -> 0.13804 | M41: {=SUMPRODUCT(Table1[Actual Cost USD]*(Table1[Level 2]="Surface Facilities Cost")*(Table1[Campaign]=tab_DB_Temp[[#This Row],[Campaign]]))/tab_DB_Temp[[#This Row],[No of Wells Drilled]]/1000000} -> 0.43605517 | N41: =SUM(tab_DB_Temp[[#This Row],[Well Cost USD mn]:[Surface Facilities Cost USD]])*1 -> 4.2547416 | O41: =IFERROR(INDEX(Table2[Actual depth, ft MD], MATCH(tab_DB_Temp[[#This Row],[Well]], Table2[Well Name Actual], 0))*1, 0) -> 7158 | P41: =IFERROR(INDEX(Table2[Drilling Duration, days equivalent], MATCH(tab_DB_Temp[[#This Row],[Well]], Table2[Well Name Actual],0))*1, 0) -> 14.854167

Sheet Pivots>>

Sheet Pivot.Master
A1: Place Holder | H1: Campaign Well Cost | O1: # of wells drilled | V1: $mn/well | AD1: $/ft | AL1: $k/day | AS1: Cumulative Depth | BA1: Cumulative Days | BL1: Complete $/ft and $k/day | BU1: Complete $/ft and $k/day as Campaign | CC1: Campaign Well Cost | CM1: Well Name (WellView Version)
BZ2: Normalized to DRJ - 2019 | CM2: AWI 10-4
A3: Asset_Label | B3: Camp_Label | C3: Well | D3: $/ft | E3: $000/day | F3: $mn/well | H3: Sum of Campaign Cost per Well USD | K3: Asset | O3: Average of No of Wells Drilled | R3: Asset | V3: $mn/well | Y3: Asset | AD3: $/ft | AG3: Asset | AL3: $000/day | AO3: Asset | AS3: Cumulative Depth ft | AV3: Asset | BA3: Cumulative days | BD3: Asset | BL3: Asset_Label | BM3: Campaign | BN3: Well | BO3: $/ft | BP3: $000/day | BU3: Asset_Label | BV3: Campaign | BW3: Well | BX3: $/ft | BY3: $000/day | BZ3: $/ft Norm | CA3: $000/day Norm | CC3: Asset_Label | CD3: Campaign | CE3: Well | CF3: Avg. Well Cost per Well $mn/well | CG3: Avg. Drill Shared Cost per Well $mn/well | CH3: Avg. Support Cost per well $mn/well | CI3: Avg. Surface Facility per well $mn/well | CJ3: Total | CM3: AWI 16-8
A4: Darajat | B4: DRJ - 2019 | C4: DRJ-44OH | F4: 1.4383081 | H4: Asset_Label | I4: Campaign | J4: Well | K4: Darajat | L4: Salak | M4: Wayang Windu | O4: Asset_Label | P4: Campaign | Q4: Well | R4: Darajat | S4: Salak | T4: Wayang Windu | V4: Asset_Label | W4: Campaign | X4: Well | Y4: Darajat | Z4: Salak | AA4: Wayang Windu | AD4: Asset_Label | AE4: Campaign | AF4: Well | AG4: Darajat | AH4: Salak | AI4: Wayang Windu | AL4: Asset_Label | AM4: Campaign | AN4: Well | AO4: Darajat | AP4: Salak | AQ4: Wayang Windu | AS4: Asset_Label | AT4: Campaign | AU4: Well | AV4: Darajat | AW4: Salak | AX4: Wayang Windu | BA4: Asset_Label | BB4: Campaign | BC4: Well | BD4: Darajat | BE4: Salak | BF4: Wayang Windu | BL4: Darajat | BM4: DRJ - 2019 | BN4: DRJ-48 | BO4: 1650.5928 | BP4: 398.29397 | BU4: Darajat | BV4: DRJ - 2019 | BX4: 8104.0679 | BY4: 1955.5407 | BZ4: =-BX4/$CA$13 -> -9.9182586 | CA4: =BY4/$CA$14 -> 1.9128506 | CC4: Darajat | CD4: DRJ - 2019 | CF4: 5.4247561 | CG4: 0.8960439 | CH4: 0.46408771 | CI4: 1.6157892 | CJ4: =SUM(CF4:CI4) -> 8.4006768 | CM4: AWI 16-9
A5: Darajat | B5: DRJ - 2019 | C5: DRJ-45OH | F5: 1.9064066 | H5: Darajat | I5: DRJ - 2019 | K5: 42.003384 | O5: Darajat | P5: DRJ - 2019 | R5: 5 | V5: Darajat | W5: DRJ - 2019 | Y5: 8.4006768 | AD5: Darajat | AE5: DRJ - 2019 | AG5: 8104.0679 | AL5: Darajat | AM5: DRJ - 2019 | AO5: 1955.5407 | AS5: Darajat | AT5: DRJ - 2019 | AV5: 5183 | BA5: Darajat | BB5: DRJ - 2019 | BD5: 21.479167 | BL5: Darajat | BM5: DRJ - 2022 | BN5: DRJ-38RD | BO5: 882.12743 | BP5: 198.41986 | BU5: Darajat | BV5: DRJ - 2022 | BX5: 4544.98 | BY5: 1022.3175 | BZ5: =-BX5/$CA$13 -> -5.5624271 | CA5: =BY5/$CA$14 -> 1 | CC5: Darajat | CD5: DRJ - 2022 | CF5: 4.0935248 | CG5: 0.91247612 | CH5: 0.38913332 | CI5: 0.73877073 | CJ5: =SUM(CF5:CI5) -> 6.133905 | CM5: AWI 21-5
A6: Darajat | B6: DRJ - 2019 | C6: DRJ-46OH | F6: 1.7890145 | H6: Darajat | I6: DRJ - 2022 | K6: 30.669525 | O6: Darajat | P6: DRJ - 2022 | R6: 5 | V6: Darajat | W6: DRJ - 2022 | Y6: 6.133905 | AD6: Darajat | AE6: DRJ - 2022 | AG6: 4544.98 | AL6: Darajat | AM6: DRJ - 2022 | AO6: 1022.3175 | AS6: Darajat | AT6: DRJ - 2022 | AV6: 6748 | BA6: Darajat | BB6: DRJ - 2022 | BD6: 30 | BL6: Darajat | BM6: DRJ - 2024 | BN6: DRJ-53 | BO6: 946.67477 | BP6: 270.23104 | BU6: Darajat | BV6: DRJ - 2024 | BX6: 1204.8465 | BY6: 267.18625 | BZ6: =-BX6/$CA$13 -> -1.4745655 | CA6: =BY6/$CA$14 -> 0.26135349 | CC6: Darajat | CD6: DRJ - 2024 | CF6: 4.9296095 | CG6: 1.0340317 | CH6: 0.38862086 | CI6: 1.1211599 | CJ6: =SUM(CF6:CI6) -> 7.4734219 | CM6: AWI 21-6
A7: Darajat | B7: DRJ - 2019 | C7: DRJ-47OH | F7: 1.5559432 | H7: Darajat | I7: DRJ - 2024 | K7: 37.36711 | O7: Darajat | P7: DRJ - 2024 | R7: 5 | V7: Darajat | W7: DRJ - 2024 | Y7: 7.4734219 | AD7: Darajat | AE7: DRJ - 2024 | AG7: 1204.8465 | AL7: Darajat | AM7: DRJ - 2024 | AO7: 267.18625 | AS7: Darajat | AT7: DRJ - 2024 | AV7: 31014 | BA7: Darajat | BB7: DRJ - 2024 | BD7: 139.85417 | BL7: Darajat | BM7: DRJ - 2024 | BN7: DRJ-54 | BO7: 1285.8941 | BP7: 260.49236 | BU7: Salak | BV7: SLK - 2021 | BX7: 3145.1113 | BY7: 1275.0567 | BZ7: =-BX7/$CA$13 -> -3.8491814 | CA7: =BY7/$CA$14 -> 1.2472218 | CC7: Salak | CD7: SLK - 2021 | CF7: 3.4772728 | CG7: 1.1168216 | CH7: 0.27674021 | CI7: 0.73941495 | CJ7: =SUM(CF7:CI7) -> 5.6102495 | CM7: AWI 21-7
A8: Darajat | B8: DRJ - 2019 | C8: DRJ-48 | D8: 1650.5928 | E8: 398.29397 | F8: 1.7110045 | H8: Salak | I8: SLK - 2021 | L8: 28.051248 | O8: Salak | P8: SLK - 2021 | S8: 5 | V8: Salak | W8: SLK - 2021 | Z8: 5.6102495 | AD8: Salak | AE8: SLK - 2021 | AH8: 3145.1113 | AL8: Salak | AM8: SLK - 2021 | AP8: 1275.0567 | AS8: Salak | AT8: SLK - 2021 | AW8: 8919 | BA8: Salak | BB8: SLK - 2021 | BE8: 22 | BL8: Darajat | BM8: DRJ - 2024 | BN8: DRJ-55 | BO8: 1150.6259 | BP8: 378.7203 | BU8: Salak | BV8: SLK - 2025 | BX8: 817.08577 | BY8: 308.20429 | BZ8: =-BX8/$CA$13 -> -1 | CA8: =BY8/$CA$14 -> 0.3014761 | CC8: Salak | CD8: SLK - 2025 | CF8: 2.9392517 | CG8: 0.60167902 | CH8: 0.22584717 | CI8: 0.5134805 | CJ8: =SUM(CF8:CI8) -> 4.2802584 | CM8: AWI 21-8
A9: Darajat | B9: DRJ - 2022 | C9: DRJ-38RD | D9: 882.12743 | E9: 198.41986 | F9: 1.1905192 | H9: Salak | I9: SLK - 2025 | L9: 38.522326 | O9: Salak | P9: SLK - 2025 | S9: 9 | V9: Salak | W9: SLK - 2025 | Z9: 4.2802584 | AD9: Salak | AE9: SLK - 2025 | AH9: 817.08577 | AL9: Salak | AM9: SLK - 2025 | AP9: 308.20429 | AS9: Salak | AT9: SLK - 2025 | AW9: 47146 | BA9: Salak | BB9: SLK - 2025 | BE9: 124.98958 | BL9: Darajat | BM9: DRJ - 2024 | BN9: DRJ-56 | BO9: 1456.8909 | BP9: 188.21944 | BU9: Wayang Windu | BV9: WW - 2018 | BX9: 1573.8613 | BY9: 190.69277 | BZ9: =-BX9/$CA$13 -> -1.9261886 | CA9: =BY9/$CA$14 -> 0.18652989 | CC9: Wayang Windu | CD9: WW - 2018 | CF9: 6.1998015 | CG9: 0.26513801 | CH9: 0.065259265 | CI9: 0.21655118 | CJ9: =SUM(CF9:CI9) -> 6.74675 | CM9: AWI 23-1
A10: Darajat | B10: DRJ - 2022 | C10: DRJ-49OH | F10: 1.3646513 | H10: Wayang Windu | I10: WW - 2018 | M10: 26.987 | O10: Wayang Windu | P10: WW - 2018 | T10: 4 | V10: Wayang Windu | W10: WW - 2018 | AA10: 6.74675 | AD10: Wayang Windu | AE10: WW - 2018 | AI10: 1573.8613 | AL10: Wayang Windu | AM10: WW - 2018 | AQ10: 190.69277 | AS10: Wayang Windu | AX10: 43546 | BA10: Wayang Windu | BB10: WW - 2018 | BF10: 141.52083 | BL10: Darajat | BM10: DRJ - 2024 | BN10: DRJ-57 | BO10: 1184.4684 | BP10: 376.9358 | BU10: Wayang Windu | BV10: WW - 2021 | BX10: 1025.607 | BY10: 245.39273 | BZ10: =-BX10/$CA$13 -> -1.2552011 | CA10: =BY10/$CA$14 -> 0.24003574 | CC10: Wayang Windu | CD10: WW - 2021 | CF10: 3.1608908 | CG10: 0.77751374 | CH10: 0.13804 | CI10: 0.43605517 | CJ10: =SUM(CF10:CI10) -> 4.5124997 | CM10: AWI 23-2
A11: Darajat | B11: DRJ - 2022 | C11: DRJ-50OH | F11: 1.2214367 | H11: Wayang Windu | I11: WW - 2021 | M11: 27.074998 | O11: Wayang Windu | P11: WW - 2021 | T11: 6 | V11: Wayang Windu | W11: WW - 2021 | AA11: 4.5124997 | AD11: Wayang Windu | AE11: WW - 2021 | AI11: 1025.607 | AL11: Wayang Windu | AM11: WW - 2021 | AQ11: 245.39273 | BA11: Wayang Windu | BB11: WW - 2021 | BF11: 110.33333 | BL11: Salak | BM11: SLK - 2021 | BN11: AWI 9-10 | BO11: 643.44095 | BP11: 260.85681 | CM11: AWI 2-6
A12: Darajat | B12: DRJ - 2022 | C12: DRJ-51OH | F12: 1.2477727 | BL12: Salak | BM12: SLK - 2025 | BN12: AWI 21-7 | BO12: 894.23151 | BP12: 275.62303 | BU12: For Label $ft/norm | BZ12: Denominator | CM12: AWI 2-7 ML
A13: Darajat | B13: DRJ - 2022 | C13: DRJ-52OH | F13: 1.1095252 | BL13: Salak | BM13: SLK - 2025 | BN13: AWI 21-8 | BO13: 1116.7281 | BP13: 325.38916 | BU13: =-BZ4 -> 9.9182586 | BZ13: $/ft | CA13: =BX8 -> 817.08577 | CM13: AWI 3-9
A14: Darajat | B14: DRJ - 2024 | C14: DRJ-53 | D14: 946.67477 | E14: 270.23104 | F14: 1.2306772 | BL14: Salak | BM14: SLK - 2025 | BN14: AWI 23-1 | BO14: 691.21634 | BP14: 454.15279 | BU14: =-BZ5 -> 5.5624271 | BZ14: $/day | CA14: =BY5 -> 1022.3175 | CM14: AWI 8-3
A15: Darajat | B15: DRJ - 2024 | C15: DRJ-54 | D15: 1285.8941 | E15: 260.49236 | F15: 1.5466734 | BL15: Salak | BM15: SLK - 2025 | BN15: AWI 23-2 | BO15: 703.94379 | BP15: 283.33737 | BU15: =-BZ6 -> 1.4745655 | CM15: AWI 9-10
A16: Darajat | B16: DRJ - 2024 | C16: DRJ-55 | D16: 1150.6259 | E16: 378.7203 | F16: 1.3807511 | BL16: Salak | BM16: SLK - 2025 | BN16: AWI 2-6 | BO16: 669.30262 | BP16: 332.41862 | BU16: =-BZ7 -> 3.8491814 | CM16: AWI 9-11
A17: Darajat | B17: DRJ - 2024 | C17: DRJ-56 | D17: 1456.8909 | E17: 188.21944 | F17: 1.8939581 | BL17: Salak | BM17: SLK - 2025 | BN17: AWI 2-7 ML | BO17: 1102.7339 | BP17: 233.14339 | BU17: =-BZ8 -> 1 | CM17: DRJ-16
A18: Darajat | B18: DRJ - 2024 | C18: DRJ-57 | D18: 1184.4684 | E18: 376.9358 | F18: 1.4213621 | BL18: Salak | BM18: SLK - 2025 | BN18: AWI 3-9 | BO18: 911.06561 | BP18: 398.21411 | BU18: =-BZ9 -> 1.9261886 | CM18: DRJ-37
A19: Salak | B19: SLK - 2021 | C19: AWI 16-08 | F19: 1.5186001 | BL19: Salak | BM19: SLK - 2025 | BN19: AWI 9-11 | BO19: 322.73511 | BP19: 128.14482 | BU19: =-BZ10 -> 1.2552011 | CM19: DRJ-38
A20: Salak | B20: SLK - 2021 | C20: AWI 16-09 | F20: 1.0383765 | BL20: Wayang Windu | BM20: WW - 2018 | BN20: MBA-6 | BO20: 880.33478 | BP20: 185.17721 | CM20: DRJ-38RD
A21: Salak | B21: SLK - 2021 | C21: Awi 21-05 | F21: 1.0489579 | BL21: Wayang Windu | BM21: WW - 2018 | BN21: MBA-7 | BO21: 1001.0138 | BP21: 199.63315 | CM21: DRJ-44
A22: Salak | B22: SLK - 2021 | C22: Awi 21-06 | F22: 0.8565451 | BL22: Wayang Windu | BM22: WW - 2018 | BN22: MBD-7 | BO22: 3135.6012 | BP22: 186.82185 | CM22: DRJ-45
A23: Salak | B23: SLK - 2021 | C23: AWI 9-10 | D23: 643.44095 | E23: 260.85681 | F23: 1.14777 | BL23: Wayang Windu | BM23: WW - 2018 | BN23: MBD-8 | BO23: 2349.6736 | BP23: 192.23019 | CM23: DRJ-46
A24: Salak | B24: SLK - 2025 | C24: AWI 21-7 | D24: 894.23151 | E24: 275.62303 | F24: 0.50275683 | BL24: Wayang Windu | BM24: WW - 2021 | BN24: MBE-6 | BO24: 864.76638 | BP24: 255.52604 | CM24: DRJ-47
A25: Salak | B25: SLK - 2025 | C25: AWI 21-8 | D25: 1116.7281 | E25: 325.38916 | F25: 0.50314806 | BL25: Wayang Windu | BM25: WW - 2021 | BN25: MBE-7 | BO25: 684.19484 | BP25: 200.53946 | CM25: DRJ-48
A26: Salak | B26: SLK - 2025 | C26: AWI 23-1 | D26: 691.21634 | E26: 454.15279 | F26: 0.69121634 | BL26: Wayang Windu | BM26: WW - 2021 | BN26: MBI-1 | BO26: 755.9035 | BP26: 299.47627 | CM26: DRJ-49
A27: Salak | B27: SLK - 2025 | C27: AWI 23-2 | D27: 703.94379 | E27: 283.33737 | F27: 0.62963861 | BL27: Wayang Windu | BM27: WW - 2021 | BN27: WWA-8 | BO27: 1264.9769 | BP27: 147.19647 | CM27: DRJ-50
A28: Salak | B28: SLK - 2025 | C28: AWI 2-6 | D28: 669.30262 | E28: 332.41862 | F28: 0.40782839 | BL28: Wayang Windu | BM28: WW - 2021 | BN28: WWA-9 | BO28: 811.0449 | BP28: 286.43421 | CM28: DRJ-51
A29: Salak | B29: SLK - 2025 | C29: AWI 2-7 ML | D29: 1102.7339 | E29: 233.14339 | F29: 0.67352536 | CM29: DRJ-52
A30: Salak | B30: SLK - 2025 | C30: AWI 3-9 | D30: 911.06561 | E30: 398.21411 | F30: 0.55676232 | CM30: DRJ-53
A31: Salak | B31: SLK - 2025 | C31: AWI 9-10 RD | F31: 0.15401494 | CM31: DRJ-54
A32: Salak | B32: SLK - 2025 | C32: AWI 9-11 | D32: 322.73511 | E32: 128.14482 | F32: 0.16136756 | CM32: DRJ-55
A33: Wayang Windu | B33: WW - 2018 | C33: MBA-6 | D33: 880.33478 | E33: 185.17721 | F33: 1.2615197 | CM33: DRJ-56
A34: Wayang Windu | B34: WW - 2018 | C34: MBA-7 | D34: 1001.0138 | E34: 199.63315 | F34: 1.2425084 | CM34: DRJ-57
A35: Wayang Windu | B35: WW - 2018 | C35: MBD-7 | D35: 3135.6012 | E35: 186.82185 | F35: 1.8108097 | CM35: HMD-A01
A36: Wayang Windu | B36: WW - 2018 | C36: MBD-8 | D36: 2349.6736 | E36: 192.23019 | F36: 2.4319121 | CM36: HMD-A02
A37: Wayang Windu | B37: WW - 2021 | C37: MBD-8WO | F37: 0.69468586 | CM37: MBA-6
A38: Wayang Windu | B38: WW - 2021 | C38: MBE-6 | D38: 864.76638 | E38: 255.52604 | F38: 0.64857478 | CM38: MBA-7
A39: Wayang Windu | B39: WW - 2021 | C39: MBE-7 | D39: 684.19484 | E39: 200.53946 | F39: 0.80563943 | CM39: MBD-7
A40: Wayang Windu | B40: WW - 2021 | C40: MBI-1 | D40: 755.9035 | E40: 299.47627 | F40: 0.54488044 | CM40: MBD-8
...

Sheet Source.Data>>

Sheet Piv.Struct.Cost
A3: Sum of Actual Cost USD | D3: Level 2 | K3: Campaign | L3: Well | M3: Level 2 | N3: Level 3 | O3: Level 4 | P3: Level 5 | Q3: Sum of Actual Cost USD
A4: Asset | B4: Campaign | C4: Well | D4: Contingency | E4: Drilling Cost | F4: Support Cost | G4: Surface Facilities Cost | K4: WW - 2018 | L4: General | M4: Drilling Cost | N4: Well Cost | O4: Drilling Operation Water Support | P4: Drilling Operation Water Support | Q4: 4904.05
A5: Darajat | B5: DRJ - 2019 | C5: DRJ-44OH | E5: 4215619.7 | K5: WW - 2018 | L5: General | M5: Drilling Cost | N5: Well Cost | O5: Material - LL | P5: Casing | Q5: 0
A6: Darajat | B6: DRJ - 2019 | C6: DRJ-45OH | E6: 6556112 | K6: WW - 2018 | L6: General | M6: Drilling Cost | N6: Well Cost | O6: Material - LL | P6: Fuel & Lubricants | Q6: 0
A7: Darajat | B7: DRJ - 2019 | C7: DRJ-46OH | E7: 5969151.8 | K7: WW - 2018 | L7: General | M7: Drilling Cost | N7: Well Cost | O7: Material - LL | P7: Well Equipment Surface | Q7: 0
A8: Darajat | B8: DRJ - 2019 | C8: DRJ-47OH | E8: 4803795 | K8: WW - 2018 | L8: General | M8: Drilling Cost | N8: Well Cost | O8: Services | P8: API non API Machine Shop Service | Q8: -228196.52
A9: Darajat | B9: DRJ - 2019 | C9: DRJ-48 | E9: 5579101.8 | K9: WW - 2018 | L9: General | M9: Drilling Cost | N9: Well Cost | O9: Services | P9: Bits, Reamer and Core heads | Q9: 0
A10: Darajat | B10: DRJ - 2019 | C10: General | E10: 4480219.5 | F10: 2320438.6 | G10: 8078945.8 | K10: WW - 2018 | L10: General | M10: Drilling Cost | N10: Well Cost | O10: Services | P10: Casing Installation | Q10: 0
A11: Darajat | B11: DRJ - 2022 | C11: DRJ-38RD | E11: 3912215.7 | K11: WW - 2018 | L11: General | M11: Drilling Cost | N11: Well Cost | O11: Services | P11: Cement, Cementing & Pump Fees | Q11: 0
A12: Darajat | B12: DRJ - 2022 | C12: DRJ-49OH | E12: 4782876.2 | K12: WW - 2018 | L12: General | M12: Drilling Cost | N12: Well Cost | O12: Services | P12: Contract Rig | Q12: -557.92
A13: Darajat | B13: DRJ - 2022 | C13: DRJ-50OH | E13: 4066803.2 | K13: WW - 2018 | L13: General | M13: Drilling Cost | N13: Well Cost | O13: Services | P13: Directional Drilling & Surveys | Q13: 0
A14: Darajat | B14: DRJ - 2022 | C14: DRJ-51OH | E14: 4198483.2 | K14: WW - 2018 | L14: General | M14: Drilling Cost | N14: Well Cost | O14: Services | P14: Drilling Safety, Health & Environment | Q14: -116.55
A15: Darajat | B15: DRJ - 2022 | C15: DRJ-52OH | E15: 3507245.7 | K15: WW - 2018 | L15: General | M15: Drilling Cost | N15: Well Cost | O15: Services | P15: Equipment Rental | Q15: 0
A16: Darajat | B16: DRJ - 2022 | C16: General | E16: 4562380.6 | F16: 1945666.6 | G16: 3693853.6 | K16: WW - 2018 | L16: General | M16: Drilling Cost | N16: Well Cost | O16: Services | P16: Land Transportation | Q16: -5927.89
A17: Darajat | B17: DRJ - 2024 | C17: DRJ-53 | E17: 3609573.6 | K17: WW - 2018 | L17: General | M17: Drilling Cost | N17: Well Cost | O17: Services | P17: Mud Logging Service | Q17: -15683.35
A18: Darajat | B18: DRJ - 2024 | C18: DRJ-54 | E18: 5189554.6 | K18: WW - 2018 | L18: General | M18: Drilling Cost | N18: Well Cost | O18: Services | P18: Mud, Chemical and Engineering Service | Q18: 0
A19: Darajat | B19: DRJ - 2024 | C19: DRJ-55 | E19: 4359943.1 | K19: WW - 2018 | L19: General | M19: Drilling Cost | N19: Well Cost | O19: Services | P19: Open Hole Electrical Logging Service | Q19: 0
A20: Darajat | B20: DRJ - 2024 | C20: DRJ-56 | E20: 6925978.2 | K20: WW - 2018 | L20: General | M20: Drilling Cost | N20: Well Cost | O20: Services | P20: Other Transportation | Q20: 0
A21: Darajat | B21: DRJ - 2024 | C21: DRJ-57 | E21: 4562998 | K21: WW - 2018 | L21: General | M21: Drilling Cost | N21: Well Cost | O21: Services | P21: Others | Q21: 1251014.3
A22: Darajat | B22: DRJ - 2024 | C22: General | E22: 5170158.4 | F22: 1943104.3 | G22: 5605799.4 | K22: WW - 2018 | L22: General | M22: Drilling Cost | N22: Well Cost | O22: Services | P22: Service Lines & Communication | Q22: 0
A23: Salak | B23: SLK - 2021 | C23: AWI 16-08 | E23: 5460023.5 | K23: WW - 2018 | L23: General | M23: Drilling Cost | N23: Well Cost | O23: Services | P23: Supervision | Q23: 0
A24: Salak | B24: SLK - 2021 | C24: AWI 16-09 | E24: 3058905.8 | K24: WW - 2018 | L24: MBA-6 | M24: Drilling Cost | N24: Well Cost | O24: Drilling Operation Water Support | P24: Drilling Operation Water Support | Q24: 12864.21
A25: Salak | B25: SLK - 2021 | C25: Awi 21-05 | E25: 3111812.8 | K25: WW - 2018 | L25: MBA-6 | M25: Drilling Cost | N25: Well Cost | O25: Material - LL | P25: Casing | Q25: 395838.88
A26: Salak | B26: SLK - 2021 | C26: Awi 21-06 | E26: 2149748.7 | K26: WW - 2018 | L26: MBA-6 | M26: Drilling Cost | N26: Well Cost | O26: Material - LL | P26: Equipment Rental | Q26: 457313.66
A27: Salak | B27: SLK - 2021 | C27: AWI 9-10 | E27: 3605873 | K27: WW - 2018 | L27: MBA-6 | M27: Drilling Cost | N27: Well Cost | O27: Material - LL | P27: Fuel & Lubricants | Q27: 133859.92
A28: Salak | B28: SLK - 2021 | C28: General | E28: 5584108 | F28: 1383701.1 | G28: 3697074.7 | K28: WW - 2018 | L28: MBA-6 | M28: Drilling Cost | N28: Well Cost | O28: Material - LL | P28: Well Equipment Surface | Q28: 76817.64
A29: Salak | B29: SLK - 2025 | C29: AWI 21-7 | E29: 3183804.8 | K29: WW - 2018 | L29: MBA-6 | M29: Drilling Cost | N29: Well Cost | O29: Services | P29: API non API Machine Shop Service | Q29: 103071.13
A30: Salak | B30: SLK - 2025 | C30: AWI 21-8 | E30: 3187325.8 | K30: WW - 2018 | L30: MBA-6 | M30: Drilling Cost | N30: Well Cost | O30: Services | P30: Bits, Reamer and Core heads | Q30: -12705
A31: Salak | B31: SLK - 2025 | C31: AWI 23-1 | E31: 4879940.4 | K31: WW - 2018 | L31: MBA-6 | M31: Drilling Cost | N31: Well Cost | O31: Services | P31: Casing Installation | Q31: 75718.2
A32: Salak | B32: SLK - 2025 | C32: AWI 23-2 | E32: 4325740.8 | K32: WW - 2018 | L32: MBA-6 | M32: Drilling Cost | N32: Well Cost | O32: Services | P32: Cement, Cementing & Pump Fees | Q32: 439716.99
A33: Salak | B33: SLK - 2025 | C33: AWI 2-6 | E33: 2329448.9 | K33: WW - 2018 | L33: MBA-6 | M33: Drilling Cost | N33: Well Cost | O33: Services | P33: Contract Rig | Q33: 1543621.9
A34: Salak | B34: SLK - 2025 | C34: AWI 2-7 ML | E34: 4720721.5 | K34: WW - 2018 | L34: MBA-6 | M34: Drilling Cost | N34: Well Cost | O34: Services | P34: Directional Drilling & Surveys | Q34: 334786.2
A35: Salak | B35: SLK - 2025 | C35: AWI 3-9 | E35: 3669854.2 | K35: WW - 2018 | L35: MBA-6 | M35: Drilling Cost | N35: Well Cost | O35: Services | P35: Drilling Safety, Health & Environment | Q35: 71177
A36: Salak | B36: SLK - 2025 | C36: AWI 9-10 RD | E36: 45127.74 | K36: WW - 2018 | L36: MBA-6 | M36: Drilling Cost | N36: Well Cost | O36: Services | P36: Equipment Rental | Q36: -141778.44
A37: Salak | B37: SLK - 2025 | C37: AWI 9-11 | E37: 111301.31 | K37: WW - 2018 | L37: MBA-6 | M37: Drilling Cost | N37: Well Cost | O37: Services | P37: Land Transportation | Q37: 117550.47
A38: Salak | B38: SLK - 2025 | C38: General | D38: 0 | E38: 5415111.2 | F38: 2032624.5 | G38: 4621324.5 | K38: WW - 2018 | L38: MBA-6 | M38: Drilling Cost | N38: Well Cost | O38: Services | P38: Mud Logging Service | Q38: 68207.7
A39: Wayang Windu | B39: WW - 2018 | C39: General | E39: 1060552 | F39: 261037.06 | G39: 866204.72 | K39: WW - 2018 | L39: MBA-6 | M39: Drilling Cost | N39: Well Cost | O39: Services | P39: Mud, Chemical and Engineering Service | Q39: 417750.09
A40: Wayang Windu | B40: WW - 2018 | C40: MBA-6 | E40: 4499130.5 | K40: WW - 2018 | L40: MBA-6 | M40: Drilling Cost | N40: Well Cost | O40: Services | P40: Other Transportation | Q40: 200544.73
A41: Wayang Windu | B41: WW - 2018 | C41: MBA-7 | E41: 4423085.2 | K41: WW - 2018 | L41: MBA-6 | M41: Drilling Cost | N41: Well Cost | O41: Services | P41: Others | Q41: 17890.25
A42: Wayang Windu | B42: WW - 2018 | C42: MBD-7 | E42: 6696290.2 | K42: WW - 2018 | L42: MBA-6 | M42: Drilling Cost | N42: Well Cost | O42: Services | P42: Service Lines & Communication | Q42: 1752.74
...

Sheet Structured.Cost
B2: # | C2: Asset | D2: Campaign | E2: Level 2 | F2: Level 3 | G2: Level 4 | H2: Level 5 | I2: Well | J2: Actual Cost USD
B3: 1 | C3: Wayang Windu | D3: WW - 2018 | E3: Drilling Cost | F3: LIH | G3: LIH | H3: LIH | I3: General | J3: -105457.27
B4: 2 | C4: Wayang Windu | D4: WW - 2018 | E4: Drilling Cost | F4: Logging Cost | G4: Logging Cost | H4: Logging Cost | I4: General | J4: 160573.24
B5: 3 | C5: Wayang Windu | D5: WW - 2018 | E5: Drilling Cost | F5: Well Cost | G5: Material - LL | H5: Casing | I5: General | J5: 0
B6: 4 | C6: Wayang Windu | D6: WW - 2018 | E6: Drilling Cost | F6: Well Cost | G6: Material - LL | H6: Casing | I6: MBA-6 | J6: 11935.55
B7: 5 | C7: Wayang Windu | D7: WW - 2018 | E7: Drilling Cost | F7: Well Cost | G7: Material - LL | H7: Casing | I7: MBA-7 | J7: 325171.97
B8: 6 | C8: Wayang Windu | D8: WW - 2018 | E8: Drilling Cost | F8: Well Cost | G8: Material - LL | H8: Casing | I8: MBD-7 | J8: 299595.79
B9: 7 | C9: Wayang Windu | D9: WW - 2018 | E9: Drilling Cost | F9: Well Cost | G9: Material - LL | H9: Casing | I9: MBD-8 | J9: 304089.61
B10: 8 | C10: Wayang Windu | D10: WW - 2018 | E10: Drilling Cost | F10: Well Cost | G10: Material - LL | H10: Fuel & Lubricants | I10: General | J10: -149146.03
B11: 9 | C11: Wayang Windu | D11: WW - 2018 | E11: Drilling Cost | F11: Well Cost | G11: Material - LL | H11: Fuel & Lubricants | I11: MBA-6 | J11: 133859.92
B12: 10 | C12: Wayang Windu | D12: WW - 2018 | E12: Drilling Cost | F12: Well Cost | G12: Material - LL | H12: Fuel & Lubricants | I12: MBA-7 | J12: 217969.05
B13: 11 | C13: Wayang Windu | D13: WW - 2018 | E13: Drilling Cost | F13: Well Cost | G13: Material - LL | H13: Fuel & Lubricants | I13: MBD-7 | J13: 397730.2
B14: 12 | C14: Wayang Windu | D14: WW - 2018 | E14: Drilling Cost | F14: Well Cost | G14: Material - LL | H14: Fuel & Lubricants | I14: MBD-8 | J14: 432393.83
... B121: 119 | C121: Wayang Windu | D121: WW - 2018 | E121: Drilling Cost | F121: Well Cost | G121: Services | H121: Others | I121: General | J121: 476192.46
B122: 120 | C122: Wayang Windu | D122: WW - 2018 | E122: Drilling Cost | F122: Well Cost | G122: =VLOOKUP(Table1[[#This Row],[Level 5]],[1]Sheet1!$C$2:$D$79,2,0) -> Services | H122: Service Lines & Communication | I122: General | J122: 3010.93
B123: 121 | C123: Wayang Windu | D123: WW - 2018 | E123: Drilling Cost | F123: Well Cost | G123: =VLOOKUP(Table1[[#This Row],[Level 5]],[1]Sheet1!$C$2:$D$79,2,0) -> Drilling Operation Water Support | H123: Drilling Operation Water Support | I123: General | J123: 4904.05
B124: 122 | C124: Wayang Windu | D124: WW - 2018 | E124: Drilling Cost | F124: Well Cost | G124: =VLOOKUP(Table1[[#This Row],[Level 5]],[1]Sheet1!$C$2:$D$79,2,0) -> Services | H124: Contract Rig | I124: General | J124: 1866987.6
B125: 123 | C125: Wayang Windu | D125: WW - 2018 | E125: Drilling Cost | F125: Well Cost | G125: =VLOOKUP(Table1[[#This Row],[Level 5]],[1]Sheet1!$C$2:$D$79,2,0) -> Services | H125: Casing Installation | I125: General | J125: 10421.91
B126: 124 | C126: Wayang Windu | D126: WW - 2018 | E126: Drilling Cost | F126: Well Cost | G126: =VLOOKUP(Table1[[#This Row],[Level 5]],[1]Sheet1!$C$2:$D$79,2,0) -> Services | H126: Cement, Cementing & Pump Fees | I126: General | J126: 174558.94
B127: 125 | C127: Wayang Windu | D127: WW - 2018 | E127: Drilling Cost | F127: Well Cost | G127: =VLOOKUP(Table1[[#This Row],[Level 5]],[1]Sheet1!$C$2:$D$79,2,0) -> Services | H127: Mud Logging Service | I127: General | J127: 16400
B128: 126 | C128: Wayang Windu | D128: WW - 2018 | E128: Drilling Cost | F128: Well Cost | G128: =VLOOKUP(Table1[[#This Row],[Level 5]],[1]Sheet1!$C$2:$D$79,2,0) -> Services | H128: Supervision | I128: General | J128: 111731.14
B129: 127 | C129: Wayang Windu | D129: WW - 2018 | E129: Drilling Cost | F129: Well Cost | G129: =VLOOKUP(Table1[[#This Row],[Level 5]],[1]Sheet1!$C$2:$D$79,2,0) -> Services | H129: Land Transportation | I129: General | J129: 32683.58
B130: 128 | C130: Wayang Windu | D130: WW - 2018 | E130: Drilling Cost | F130: Well Cost | G130: =VLOOKUP(Table1[[#This Row],[Level 5]],[1]Sheet1!$C$2:$D$79,2,0) -> Services | H130: Other Transportation | I130: General | J130: 16983.19
B131: 129 | C131: Wayang Windu | D131: WW - 2018 | E131: Drilling Cost | F131: Well Cost | G131: =VLOOKUP(Table1[[#This Row],[Level 5]],[1]Sheet1!$C$2:$D$79,2,0) -> Material - LL | H131: Fuel & Lubricants | I131: General | J131: 149146.03
B132: 130 | C132: Wayang Windu | D132: WW - 2018 | E132: Drilling Cost | F132: Well Cost | G132: Services | H132: Others | I132: General | J132: 69.37
B133: 131 | C133: Wayang Windu | D133: WW - 2018 | E133: Drilling Cost | F133: Well Cost | G133: =VLOOKUP(Table1[[#This Row],[Level 5]],[1]Sheet1!$C$2:$D$79,2,0) -> Services | H133: Drilling Safety, Health & Environment | I133: General | J133: 16365.77
B134: 132 | C134: Wayang Windu | D134: WW - 2018 | E134: Drilling Cost | F134: Well Cost | G134: Services | H134: Others | I134: General | J134: 175153.08
B135: 133 | C135: Wayang Windu | D135: WW - 2018 | E135: Drilling Cost | F135: Well Cost | G135: Services | H135: Others | I135: General | J135: 580963.37
B136: 134 | C136: Wayang Windu | D136: WW - 2018 | E136: Drilling Cost | F136: Well Cost | G136: Services | H136: Others | I136: General | J136: 18635.98
B137: 136 | C137: Darajat | D137: DRJ - 2019 | E137: Drilling Cost | F137: Rig Mobilization | G137: Rig Mobilization | H137: Rig Mobilization | I137: General | J137: 3136274.4 | M137: D
B138: 137 | C138: Darajat | D138: DRJ - 2019 | E138: Drilling Cost | F138: Rig Move | G138: Interpad Move | H138: Rig Move | I138: General | J138: 1337803.5 | L138: =SUM(J137:J138) -> 4474077.9 | M138: D
B139: 138 | C139: Darajat | D139: DRJ - 2019 | E139: Drilling Cost | F139: Well Cost | G139: Material - LL | H139: Casing | I139: DRJ-44OH | J139: 367853.72
B140: 139 | C140: Darajat | D140: DRJ - 2019 | E140: Drilling Cost | F140: Well Cost | G140: Material - LL | H140: Casing | I140: DRJ-45OH | J140: 571988.4
B141: 140 | C141: Darajat | D141: DRJ - 2019 | E141: Drilling Cost | F141: Well Cost | G141: Material - LL | H141: Casing | I141: DRJ-46OH | J141: 532507.52
B142: 141 | C142: Darajat | D142: DRJ - 2019 | E142: Drilling Cost | F142: Well Cost | G142: Material - LL | H142: Casing | I142: DRJ-47OH | J142: 454605.79
B143: 142 | C143: Darajat | D143: DRJ - 2019 | E143: Drilling Cost | F143: Well Cost | G143: Material - LL | H143: Casing | I143: DRJ-48 | J143: 359868.91
B144: 143 | C144: Darajat | D144: DRJ - 2019 | E144: Drilling Cost | F144: Well Cost | G144: Material - LL | H144: Equipment Rental | I144: DRJ-44OH | J144: 370208.79
B145: 144 | C145: Darajat | D145: DRJ - 2019 | E145: Drilling Cost | F145: Well Cost | G145: Material - LL | H145: Equipment Rental | I145: DRJ-45OH | J145: 862920.21
B146: 145 | C146: Darajat | D146: DRJ - 2019 | E146: Drilling Cost | F146: Well Cost | G146: Material - LL | H146: Equipment Rental | I146: DRJ-46OH | J146: 567110.31
B147: 146 | C147: Darajat | D147: DRJ - 2019 | E147: Drilling Cost | F147: Well Cost | G147: Material - LL | H147: Equipment Rental | I147: DRJ-47OH | J147: 428314.23
...

Sheet General.Camp.Data
B2: No | C2: Asset | D2: Campaign | E2: WBS CODE | F2: Pad Name | G2: Well Name Actual | H2: Well Name SAP | I2: Well Name Alt 1 | J2: Well Name Alt 2 | K2: ST Yes or No | L2: Actual Depth Original, ft MD | M2: Actual Depth Side Track, ft MD | N2: Actual depth, ft MD | O2: Spud Date | P2: Drilling Duration, hrs | Q2: Drilling Duration, days equivalent | R2: NPT hours | S2: Target depth, ft MD | T2: Target Depth, eq. m MD | U2: Actual Depth, eq. m MD
B3: 1 | C3: Wayang Windu | D3: WW - 2018 | E3: E500-2-0-8501-185003 | F3: Pad MBA | G3: MBA-6 | H3: MBA-6 | I3: MBA-6 | J3: MBA-6 | K3: No | L3: 5732 | M3: 0 | N3: 5732 | O3: 43431.604 | P3: 654 | Q3: 27.25 | R3: 0.5 | S3: 5807 | T3: 1769.9736 | U3: =CONVERT(Table2[[#This Row],[Actual depth, ft MD]],"ft", "m") -> 1747.1136
B4: 2 | C4: Wayang Windu | D4: WW - 2018 | E4: E500-2-0-8501-185003 | F4: Pad MBA | G4: MBA-7 | H4: MBA-7 | I4: MBA-7 | J4: MBA-7 | K4: No | L4: 4965 | M4: 0 | N4: 4965 | O4: 43463.667 | P4: 597.5 | Q4: 24.895833 | R4: 36.75 | S4: 5413 | T4: 1649.8824 | U4: =CONVERT(Table2[[#This Row],[Actual depth, ft MD]],"ft", "m") -> 1513.332
B5: 3 | C5: Wayang Windu | D5: WW - 2018 | E5: E500-2-0-8501-185003 | F5: Pad MBD | G5: MBD-7 | H5: MBD-7 | I5: MBD-7 | J5: MBD-7 | K5: No | L5: 4997 | M5: 0 | N5: 4997 | O5: 43505.729 | P5: 214 | Q5: 38.770833 | R5: 3 | S5: 4997 | T5: 1523.0856 | U5: =CONVERT(Table2[[#This Row],[Actual depth, ft MD]],"ft", "m") -> 1523.0856
B6: 4 | C6: Wayang Windu | D6: WW - 2018 | E6: E500-2-0-8501-185003 | F6: Pad MBD | G6: MBD-8 | H6: MBD-8 | I6: MBD-8 | J6: MBD-8 | K6: Yes | L6: 4083 | M6: 4140 | N6: 4140 | O6: 43549.146 | P6: 1214.5 | Q6: 50.604167 | R6: 52.5 | S6: 8202 | T6: 2499.9696 | U6: =CONVERT(Table2[[#This Row],[Actual depth, ft MD]],"ft", "m") -> 1261.872
B7: 5 | C7: Darajat | D7: DRJ - 2019 | E7: E530-30101-D19001 | F7: Pad 20 | G7: DRJ-48 | H7: Well 20 02 | I7: DRJ 20 NE | J7: DRJ-48 | K7: No | L7: 5399.5 | M7: 0 | N7: 5399.5 | O7: 43876.479 | P7: 515.5 | Q7: 21.479167 | R7: 1.25 | S7: 5400 | T7: 1645.92 | U7: =CONVERT(Table2[[#This Row],[Actual depth, ft MD]],"ft", "m") -> 1645.7676
B8: 6 | C8: Darajat | D8: DRJ - 2019 | E8: E530-30101-D19001 | F8: Pad S4 | G8: DRJ-47 | H8: Well S4 03 | I8: DRJ S4 SW | J8: DRJ-47 | K8: No | L8: 5902 | M8: 0 | N8: 5902 | O8: 43826.667 | P8: 600 | Q8: 25 | R8: 3 | S8: 5902 | T8: 1798.9296 | U8: =CONVERT(Table2[[#This Row],[Actual depth, ft MD]],"ft", "m") -> 1798.9296
B9: 7 | C9: Darajat | D9: DRJ - 2019 | E9: E530-30101-D19001 | F9: Pad 20 | G9: DRJ-44 | H9: Well 20 01 | I9: DRJ 20 WNW | J9: DRJ-44 | K9: No | L9: 5860 | M9: 0 | N9: 5860 | O9: 43640.625 | P9: 598.5 | Q9: 24.9375 | R9: 1 | S9: 5979 | T9: 1822.3992 | U9: =CONVERT(Table2[[#This Row],[Actual depth, ft MD]],"ft", "m") -> 1786.128
B10: 8 | C10: Darajat | D10: DRJ - 2019 | E10: E530-30101-D19001 | F10: Pad S4 | G10: DRJ-45 | H10: Well S4 01 | I10: DRJ S4SSE | J10: DRJ-45 | K10: No | L10: 5977 | M10: 0 | N10: 5977 | O10: 43692.771 | P10: 1567.25 | Q10: 65.302083 | R10: 32 | S10: 5977 | T10: 1821.7896 | U10: =CONVERT(Table2[[#This Row],[Actual depth, ft MD]],"ft", "m") -> 1821.7896
B11: 9 | C11: Darajat | D11: DRJ - 2019 | E11: E530-30101-D19001 | F11: Pad S4 | G11: DRJ-46 | H11: Well S4 02 | I11: DRJ S4S | J11: DRJ-46 | K11: No | L11: 5836 | M11: 0 | N11: 5836 | O11: 43775.938 | P11: 976.5 | Q11: 40.6875 | R11: 2 | S11: 5735 | T11: 1748.028 | U11: =CONVERT(Table2[[#This Row],[Actual depth, ft MD]],"ft", "m") -> 1778.8128
B12: 10 | C12: Wayang Windu | D12: WW - 2021 | E12: E500-30101-D205011 | F12: Pad MBI | G12: MBI-1 | H12: MBI 1 | I12: MBI 1 | J12: MBI-1 | K12: No | L12: 4325 | M12: 0 | N12: 4325 | O12: 44343.583 | P12: 262 | Q12: 10.916667 | R12: 0.5 | S12: 4391 | T12: 1338.3768 | U12: =CONVERT(Table2[[#This Row],[Actual depth, ft MD]],"ft", "m") -> 1318.26
B13: 11 | C13: Wayang Windu | D13: WW - 2021 | E13: E500-30101-D205011 | F13: Pad WWA | G13: WWA-9 | H13: WWA 9 | I13: WWA 9 | J13: WWA-9 | K13: No | L13: 7158 | M13: 0 | N13: 7158 | O13: 44258.917 | P13: 356.5 | Q13: 14.854167 | R13: 1.5 | S13: 7191 | T13: 2191.8168 | U13: =CONVERT(Table2[[#This Row],[Actual depth, ft MD]],"ft", "m") -> 2181.7584
B14: 12 | C14: Wayang Windu | D14: WW - 2021 | E14: E500-30101-D205011 | F14: Pad WWA | G14: WWA-8 | H14: WWA 8 | I14: WWA 8 | J14: WWA-8 | K14: No | L14: 5263 | M14: 0 | N14: 5263 | O14: 44280 | P14: 1085.5 | Q14: 45.229167 | R14: 20.25 | S14: 7166 | T14: 2184.1968 | U14: =CONVERT(Table2[[#This Row],[Actual depth, ft MD]],"ft", "m") -> 1604.1624
... B16: 14 | C16: Wayang Windu | D16: WW - 2021 | E16: E500-30101-D205011 | F16: Pad MBE | G16: MBE-6 | H16: MBE 06 | I16: MBE 06 | J16: MBE-6 | K16: No | L16: 4500 | M16: 0 | N16: 4500 | O16: 44185.229 | P16: 365.5 | Q16: 15.229167 | R16: 3 | S16: 4500 | T16: 1371.6 | U16: =CONVERT(Table2[[#This Row],[Actual depth, ft MD]],"ft", "m") -> 1371.6
B17: 15 | C17: Wayang Windu | D17: WW - 2021 | E17: E500-30101-D205011 | F17: Pad MBD | G17: MBD-8WO | H17: MBD 8 WO | I17: MBD 8 WO | J17: MBD-8WO | R17: 0
B18: 16 | C18: Salak | D18: SLK - 2021 | E18: E540-30101-D20001 | F18: Pad 21 | G18: AWI 21-6 | H18: AWI 21-06 | I18: AWI 21-06 | J18: AWI 21-6 | K18: No | L18: 4918 | M18: 0 | N18: 4918 | O18: 44409.5 | P18: 214 | Q18: 8.9166667 | R18: 0 | S18: 5021 | T18: 1530.4008 | U18: =CONVERT(Table2[[#This Row],[Actual depth, ft MD]],"ft", "m") -> 1499.0064
B19: 17 | C19: Salak | D19: SLK - 2021 | E19: E540-30101-D20001 | F19: Pad 21 | G19: AWI 21-5 | H19: AWI 21-05 | I19: AWI 21-05 | J19: AWI 21-5 | K19: No | L19: 4685 | M19: 0 | N19: 4685 | O19: 44384.896 | P19: 529.5 | Q19: 22.0625 | R19: 1.75 | S19: 4846 | T19: 1477.0608 | U19: =CONVERT(Table2[[#This Row],[Actual depth, ft MD]],"ft", "m") -> 1427.988
B20: 18 | C20: Salak | D20: SLK - 2021 | E20: E540-30101-D20001 | F20: Pad 16 | G20: AWI 16-9 | H20: AWI 16-09 | I20: AWI 16-09 | J20: AWI 16-9 | K20: No | L20: 5379 | M20: 0 | N20: 5379 | O20: 44477 | P20: 438.5 | Q20: 18.270833 | R20: 0 | S20: 5591 | T20: 1704.1368 | U20: =CONVERT(Table2[[#This Row],[Actual depth, ft MD]],"ft", "m") -> 1639.5192
B21: 19 | C21: Salak | D21: SLK - 2021 | E21: E540-30101-D20001 | F21: Pad 16 | G21: AWI 16-8 | H21: AWI 16-08 | I21: AWI 16-08 | J21: AWI 16-8 | K21: Yes | L21: 4114 | M21: 5000 | N21: 5000 | O21: 44435.125 | P21: 414 | Q21: 17.25 | R21: 2.75 | S21: 5385 | T21: 1641.348 | U21: =CONVERT(Table2[[#This Row],[Actual depth, ft MD]],"ft", "m") -> 1524
B22: 20 | C22: Salak | D22: SLK - 2021 | E22: E540-30101-D20001 | F22: Pad 9 | G22: AWI 9-10 | H22: AWI 9-10 | I22: AWI 9-10 | J22: AWI 9-10 | K22: Yes | L22: 8919 | M22: 0 | N22: 8919 | O22: 44519.958 | P22: 528 | Q22: 22 | R22: 1 | S22: 9263 | T22: 2823.3624 | U22: =CONVERT(Table2[[#This Row],[Actual depth, ft MD]],"ft", "m") -> 2718.5112
B23: 21 | C23: Darajat | D23: DRJ - 2022 | E23: E530-30101-D225301 | F23: Pad 14 | G23: DRJ-51 | H23: DRJ 14-1 | I23: DRJ 14-1 | J23: DRJ-51 | K23: No | L23: 4993 | M23: 0 | N23: 4993 | O23: 44718.354 | P23: 706.5 | Q23: 29.4375 | R23: 5 | S23: 6200 | T23: 1889.76 | U23: =CONVERT(Table2[[#This Row],[Actual depth, ft MD]],"ft", "m") -> 1521.8664
B24: 22 | C24: Darajat | D24: DRJ - 2022 | E24: E530-30101-D225301 | F24: Pad 14 | G24: DRJ-52 | H24: DRJ 14-2 | I24: DRJ 14-2 | J24: DRJ-52 | K24: No | L24: 5765 | M24: 0 | N24: 5765 | O24: 44750.375 | P24: 489 | Q24: 20.375 | R24: 1.5 | S24: 6000 | T24: 1828.8 | U24: =CONVERT(Table2[[#This Row],[Actual depth, ft MD]],"ft", "m") -> 1757.172
B25: 23 | C25: Darajat | D25: DRJ - 2022 | E25: E530-30101-D225301 | F25: Pad 20 | G25: DRJ-50 | H25: DRJ 20-1 | I25: DRJ 20-1 | J25: DRJ-50 | K25: No | L25: 5749 | M25: 0 | N25: 5749 | O25: 44674.271 | P25: 701.5 | Q25: 29.229167 | R25: 1.75 | S25: 6300 | T25: 1920.24 | U25: =CONVERT(Table2[[#This Row],[Actual depth, ft MD]],"ft", "m") -> 1752.2952
B26: 24 | C26: Darajat | D26: DRJ - 2022 | E26: E530-30101-D225301 | F26: Pad SF | G26: DRJ-49 | H26: DRJ SF-1 | I26: DRJ SF-1 | J26: DRJ-49 | K26: No | L26: 6310 | M26: 0 | N26: 6310 | O26: 44626.458 | P26: 840.5 | Q26: 35.020833 | R26: 2 | S26: 6300 | T26: 1920.24 | U26: =CONVERT(Table2[[#This Row],[Actual depth, ft MD]],"ft", "m") -> 1923.288
B27: 25 | C27: Darajat | D27: DRJ - 2022 | E27: E530-30101-D225301 | F27: Pad SF | G27: DRJ-38RD | H27: DRJ SF-ML | I27: DRJ SF-ML | J27: DRJ-38RD | K27: Yes | L27: 8250.0003 | M27: 6748 | N27: 6748 | O27: 44593.5 | P27: 720 | Q27: 30 | R27: 91.5 | S27: 7000 | T27: 2133.6 | U27: =CONVERT(Table2[[#This Row],[Actual depth, ft MD]],"ft", "m") -> 2056.7904
B28: 26 | C28: Darajat | D28: DRJ - 2024 | E28: E530-30101-D235301 | F28: Pad 15 | G28: DRJ-53 | H28: DRJ Steam 6 | I28: DRJ Steam 6 | J28: DRJ-53 | K28: No | L28: 6500 | M28: 0 | N28: 6500 | O28: 45407.979 | P28: 546.5 | Q28: 22.770833 | R28: 3.5 | S28: 6500 | T28: 1981.2 | U28: =CONVERT(Table2[[#This Row],[Actual depth, ft MD]],"ft", "m") -> 1981.2
B29: 27 | C29: Darajat | D29: DRJ - 2024 | E29: E530-30101-D235301 | F29: Pad 18 | G29: DRJ-54 | H29: DRJ Steam 2 | I29: DRJ Steam 2 | J29: DRJ-54 | K29: No | L29: 6014 | M29: 0 | N29: 6014 | O29: 45443.979 | P29: 712.5 | Q29: 29.6875 | R29: 166 | S29: 6000 | T29: 1828.8 | U29: =CONVERT(Table2[[#This Row],[Actual depth, ft MD]],"ft", "m") -> 1833.0672
... B40: 38 | C40: Salak | D40: SLK - 2025 | E40: E540-30101-D245401 | F40: Pad 9 | G40: AWI 9-11 | H40: AWI 9-11 | I40: AWI 9-11 | J40: AWI 9-11 | K40: No | L40: 9000 | M40: 0 | N40: 9000 | O40: 46086.667 | P40: 0 | Q40: 11.333333 | R40: 3 | S40: 9000 | T40: 2743.2 | U40: =CONVERT(Table2[[#This Row],[Actual depth, ft MD]],"ft", "m") -> 2743.2
B41: 39 | C41: Salak | D41: SLK - 2025 | E41: E540-30101-D245401 | F41: Pad 9 | G41: AWI 9-10 RD | H41: AWI 9-10RD | I41: AWI 9-10RD | J41: AWI 9-10 RD | R41: 0

Sheet NPT.Data
B2: Non-Productive Time
B4: # | C4: Well Name | D4: Job Cat Drill / Sidetrack / Well Service | E4: Event Reference No. | F4: Start Date | G4: End Date | H4: Unsch Maj Cat | I4: Unscheduled Detail | J4: Definition | K4: Dur (Net) (hr) | L4: Accountable Party | M4: Service Contract | N4: Campaign
B5: 1 | C5: AWI 10-4 | D5: Well Services | E5: 1 | F5: 43560.458 | G5: 43560.542 | H5: WO | I5: PERSONNEL | J5: Wait On - Personnel. | K5: 2 | L5: Operator | M5: STAR | N5: =IFERROR(INDEX(Table2[Campaign], MATCH(tab_NPT[[#This Row],[Well Name]], Table2[Well Name Actual], 0)), "")
B6: 2 | C6: AWI 10-4 | D6: Drill and Complete | E6: 3 | F6: 41107.417 | G6: 41109.458 | H6: WO | I6: HES | J6: Wait On - HSE. Safety stand-downs, investigations. | K6: 49 | L6: Operator's Other Contractors | M6: Kharisma Citatunggal | N6: =IFERROR(INDEX(Table2[Campaign], MATCH(tab_NPT[[#This Row],[Well Name]], Table2[Well Name Actual], 0)), "")
B7: 5 | C7: AWI 10-4 | D7: Drill and Complete | E7: 4 | F7: 41113.25 | G7: 41124.667 | H7: WO | I7: REG PERMIT | J7: Wait On - Regulations/Permits. | K7: 274 | L7: Operator | M7: Chevron Geothermal Indonesia Ltd. | N7: =IFERROR(INDEX(Table2[Campaign], MATCH(tab_NPT[[#This Row],[Well Name]], Table2[Well Name Actual], 0)), "")
